Workbook

Sheet README
A1: Project Satoshi Gate: transaction and accretion/dilution model
A2: Paytm (One97 Communications) and Liminal Custody Solutions. All figures ₹ Cr unless stated.
A3: Purpose: supports the board recommendation to take a 24.9% stake in Liminal with a path to control, and shows why the proposed ₹4,000 Cr full acquisition destroys value.
A4: Source hierarchy: case facts govern (Case_Inputs, grey fill). Everything else is a disclosed team assumption (Assumptions, yellow fill). No external figure replaces a case input.
A5: Blue bold font = input you can change. Black = formula. Green fill = key output.
A6: Change any input on Case_Inputs, Assumptions or Scenario_Paths, or the scenario/churn/drag selectors on the path sheets, and every live sheet recalculates.
A7: Sheets marked 'values from model run' hold grids that need iteration (bisection for breakeven churn, 5x5 sensitivity, all-scenario tables). They come from model/satoshi_gate_model.py.
A8: Checks sheet: every row must read TRUE. It ties live formulas to the Python model within ±1.
A9: Sheet map: Case_Inputs, Assumptions, Scenario_Paths, Paytm_Baseline, Liminal_DCF, DCF_Sensitivity, Full_Acq, Minority, JV, Walk_Away, Paths_Summary, Churn_Drag_Grid, Funding_Credit, Football_Field, Checks.
A10: Breakeven definitions: PAT basis = first year pro-forma EPS reaches the MDR-adjusted standalone EPS (full, JV) or deal ΔPAT turns positive (minority). FCF basis = first year cumulative deal operating FCF after capital drag covers the cash consideration (full) or cumulative look-through FCF covers cash paid (minority).
A11: Model hash: 7fdbe0a3ea | generated 2026-09-24T00:06:44

Sheet Case_Inputs
A1: Case facts (governing, do not change)
A2: Source: Project Satoshi Gate case document
A4: Key | B4: Case fact | C4: Value | D4: Unit | E4: Case reference
A5: MCAP | B5: Paytm market capitalisation | C5: 118750 | D5: ₹ Cr | E5: §1
A6: SH | B6: Diluted shares outstanding | C6: 64 | D6: Cr | E6: §1
A7: CASH | B7: Cash | C7: 8900 | D7: ₹ Cr | E7: §1
A8: DEBT | B8: Gross debt | C8: 350 | D8: ₹ Cr | E8: §1
A9: REV | B9: Trailing revenue | C9: 8450 | D9: ₹ Cr | E9: §1
A10: EBITDA | B10: EBITDA | C10: 640 | D10: ₹ Cr | E10: §1
A11: PAT | B11: PAT | C11: 480 | D11: ₹ Cr | E11: §1
A12: EPS | B12: Diluted EPS | C12: 7.5 | D12: ₹ | E12: §1
A13: DEAL | B13: Deal value | C13: 4000 | D13: ₹ Cr | E13: §2
A14: DEAL_CASH | B14: Cash component | C14: 2100 | D14: ₹ Cr | E14: §2
A15: DEAL_EQ | B15: Equity component | C15: 1900 | D15: ₹ Cr | E15: §2
A16: ARR | B16: Liminal ARR | C16: 220 | D16: ₹ Cr | E16: §2 table
... A21: CH_HI | B21: ARR churn, high end (full acquisition) | C21: 0.45 | D21: % | E21: §3.1

Sheet Assumptions
A1: Team assumptions (disclosed; not case facts)
A2: IDs match the research document and the assumptions slide
A4: ID | B4: Key | C4: Parameter | D4: Value | E4: Unit | F4: Rationale / source
A5: A02 | B5: T | C5: Tax rate | D5: 0.2517 | E5: % | F5: s.115BAA new regime; carried losses ignored
A6: A03 | B6: YC | C6: Pre-tax yield on Paytm cash | D6: 0.06 | E6: % | F6: 364-day T-bill 5.74% (Aug 2026) plus treasury mix
A7: A04 | B7: KD | C7: Cost of new debt (AA- issuer) | D7: 0.0875 | E7: % | F7: AA band 8.0 to 9.5% (2026)
A8: A05 | B8: YR | C8: Yield on locked capital reserves | D8: 0.05 | E8: % | F8: RBI SDF 5.00%; 1% negative carry
A9: A07 | B9: PW | C9: Paytm WACC | D9: 0.155 | E9: % | F9: Rf 7.04% (10Y G-sec, 23 Sep 2026) + beta 1.20 x India ERP 7.08% (Damodaran Jan 2026) = 15.5%; net cash so WACC = Ke
A10: A08 | B10: LW | C10: Liminal discount rate | D10: 0.17 | E10: % | F10: Rf 7.04% + beta 1.40 x ERP 7.08% = 17.0%, all equity, crypto-infrastructure risk
A11: A09 | B11: TG | C11: Liminal terminal growth | D11: 0.06 | E11: % | F11: Below India nominal GDP growth
A12: A11a | B12: DA | C12: D&A % revenue | D12: 0.04 | E12: % | F12: Infrastructure SaaS norm
A13: A11b | B13: CAPEX | C13: Capex % revenue | D13: 0.05 | E13: % | F13: Infrastructure SaaS norm
A14: A11c | B14: NWC | C14: NWC % incremental revenue | D14: 0.02 | E14: % | F14: Infrastructure SaaS norm
A15: A12 | B15: DEC | C15: Decremental margin on churned ARR (yr 1; half in yr 2) | D15: 0.6 | E15: % | F15: Sticky costs before take-out
A16: A13a | B16: CH_FULL | C16: Churn, full acquisition (base) | D16: 0.375 | E16: % | F16: Midpoint of case 30 to 45%
... A36: A25b | B36: JV_SETUP | C36: JV set-up opex (first 2 yrs) | D36: 40 | E36: ₹ Cr/yr | F36: New entity build
A37: A26a | B37: P_BEAR | C37: Probability: bear | D37: 0.25 | E37: %
A38: A26b | B38: P_BASE | C38: Probability: base | D38: 0.5 | E38: %
A39: A26c | B39: P_BULL | C39: Probability: bull | D39: 0.25 | E39: %
A40: A29 | B40: BREAK_FEE | C40: Reverse break fee | D40: 30 | E40: ₹ Cr | F40: Paid by Paytm only if Paytm walks without a CP failure
C41: Derived: Paytm share price (A01) | D41: =Case_Inputs!$C$5/Case_Inputs!$C$6
C42: Derived: MDR-adjusted standalone EPS | D42: =(Case_Inputs!$C$11+Case_Inputs!$C$19*(1-Assumptions!$D$5))/Case_Inputs!$C$6
C43: Derived: PV of avoided build | D43: =Assumptions!$D$24*(1-Assumptions!$D$5)/Assumptions!$D$9

Sheet Scenario_Paths
A1: Scenario paths (team assumptions A10, A21)
A2: Liminal revenue growth, EBITDA margin and Paytm revenue synergy by year
A4: Liminal revenue growth | B4: Scenario | C4: FY27 | D4: FY28 | E4: FY29 | F4: FY30 | G4: FY31 | H4: FY32 | I4: FY33 | J4: FY34 | K4: FY35 | L4: FY36
B5: bear | C5: 0.22 | D5: 0.2 | E5: 0.18 | F5: 0.16 | G5: 0.14 | H5: 0.12 | I5: 0.11 | J5: 0.1 | K5: 0.09 | L5: 0.08
B6: base | C6: 0.35 | D6: 0.32 | E6: 0.28 | F6: 0.25 | G6: 0.22 | H6: 0.2 | I6: 0.18 | J6: 0.16 | K6: 0.14 | L6: 0.12
B7: bull | C7: 0.5 | D7: 0.45 | E7: 0.38 | F7: 0.32 | G7: 0.27 | H7: 0.23 | I7: 0.2 | J7: 0.17 | K7: 0.15 | L7: 0.13
A9: Liminal EBITDA margin | B9: Scenario | C9: FY27 | D9: FY28 | E9: FY29 | F9: FY30 | G9: FY31 | H9: FY32 | I9: FY33 | J9: FY34 | K9: FY35 | L9: FY36
B10: bear | C10: 0.04 | D10: 0.09 | E10: 0.13 | F10: 0.17 | G10: 0.2 | H10: 0.22 | I10: 0.23 | J10: 0.24 | K10: 0.25 | L10: 0.25
B11: base | C11: 0.08 | D11: 0.16 | E11: 0.23 | F11: 0.29 | G11: 0.33 | H11: 0.36 | I11: 0.37 | J11: 0.38 | K11: 0.38 | L11: 0.38
B12: bull | C12: 0.1 | D12: 0.2 | E12: 0.28 | F12: 0.34 | G12: 0.38 | H12: 0.4 | I12: 0.41 | J12: 0.42 | K12: 0.42 | L12: 0.42
A14: Revenue synergy to Paytm (₹ Cr) | B14: Scenario | C14: FY27 | D14: FY28 | E14: FY29 | F14: FY30 | G14: FY31 | H14: FY32 | I14: FY33 | J14: FY34 | K14: FY35 | L14: FY36
B15: bear | C15: 0 | D15: 0 | E15: 10 | F15: 20 | G15: 30 | H15: 40 | I15: 45 | J15: 50 | K15: 55 | L15: 60
B16: base | C16: 0 | D16: 10 | E16: 30 | F16: 55 | G16: 85 | H16: 110 | I16: 130 | J16: 145 | K16: 155 | L16: 165
B17: bull | C17: 0 | D17: 20 | E17: 50 | F17: 90 | G17: 130 | H17: 170 | I17: 200 | J17: 225 | K17: 245 | L17: 260

Sheet Paytm_Baseline
A1: Paytm baseline on case facts
A2: Valuation premium, MDR effect, scale of the capital drag
A3: Metric | B3: Value
A4: Share price (₹) | B4: =Assumptions!$D$41
A5: Enterprise value | B5: =Case_Inputs!$C$5-Case_Inputs!$C$7+Case_Inputs!$C$8
A6: P/E (x) | B6: =Assumptions!$D$41/Case_Inputs!$C$12
A7: EV/Revenue (x) | B7: =B5/Case_Inputs!$C$9
A8: EV/EBITDA (x) | B8: =B5/Case_Inputs!$C$10
A9: EBITDA margin | B9: =Case_Inputs!$C$10/Case_Inputs!$C$9
A10: Deal value / ARR (x) | B10: =Case_Inputs!$C$13/Case_Inputs!$C$16
A11: MDR post-tax | B11: =Case_Inputs!$C$19*(1-Assumptions!$D$5)
A12: EPS with MDR, no deal (₹) | B12: =Assumptions!$D$42
A13: MDR uplift to EPS | B13: =Assumptions!$D$42/Case_Inputs!$C$12-1
A14: MDR offset of drag, pre-tax | B14: =Case_Inputs!$C$19/Case_Inputs!$C$18
A15: MDR offset of drag, post-tax | B15: =B11/Case_Inputs!$C$18
A16: Drag / Liminal ARR (x) | B16: =Case_Inputs!$C$18/Case_Inputs!$C$16
A17: Drag / Paytm PAT | B17: =Case_Inputs!$C$18/Case_Inputs!$C$11
A18: Top-4 client ARR | B18: =Case_Inputs!$C$16*Case_Inputs!$C$17
A19: Earnings yield | B19: =Case_Inputs!$C$12/Assumptions!$D$41
A20: Post-tax cash yield | B20: =Assumptions!$D$6*(1-Assumptions!$D$5)
A21: Buyback of ₹2,100 Cr: shares retired (Cr) | B21: =Case_Inputs!$C$14/Assumptions!$D$41
A22: Buyback EPS (₹) | B22: =(Case_Inputs!$C$11-Case_Inputs!$C$14*Assumptions!$D$6*(1-Assumptions!$D$5))/(Case_Inputs!$C$6-B21)

Sheet Liminal_DCF
A1: Liminal standalone DCF by scenario (discount rate A08, terminal growth A09)
A2: Scenario | B2: bear
A3: Churn applied | B3: 0
A5: Liminal (standalone) | B5: FY26 | C5: FY27 | D5: FY28 | E5: FY29 | F5: FY30 | G5: FY31 | H5: FY32 | I5: FY33 | J5: FY34 | K5: FY35 | L5: FY36
A6: Growth | C6: =INDEX(Scenario_Paths!C$5:C$7,MATCH($B$2,Scenario_Paths!$B$5:$B$7,0)) | D6: =INDEX(Scenario_Paths!D$5:D$7,MATCH($B$2,Scenario_Paths!$B$5:$B$7,0)) | E6: =INDEX(Scenario_Paths!E$5:E$7,MATCH($B$2,Scenario_Paths!$B$5:$B$7,0)) | F6: =INDEX(Scenario_Paths!F$5:F$7,MATCH($B$2,Scenario_Paths!$B$5:$B$7,0)) | G6: =INDEX(Scenario_Paths!G$5:G$7,MATCH($B$2,Scenario_Paths!$B$5:$B$7,0)) | H6: =INDEX(Scenario_Paths!H$5:H$7,MATCH($B$2,Scenario_Paths!$B$5:$B$7,0)) | I6: =INDEX(Scenario_Paths!I$5:I$7,MATCH($B$2,Scenario_Paths!$B$5:$B$7,0)) | J6: =INDEX(Scenario_Paths!J$5:J$7,MATCH($B$2,Scenario_Paths!$B$5:$B$7,0)) | ... L6: =INDEX(Scenario_Paths!L$5:L$7,MATCH($B$2,Scenario_Paths!$B$5:$B$7,0))
A7: Margin | C7: =INDEX(Scenario_Paths!C$10:C$12,MATCH($B$2,Scenario_Paths!$B$10:$B$12,0)) | D7: =INDEX(Scenario_Paths!D$10:D$12,MATCH($B$2,Scenario_Paths!$B$10:$B$12,0)) | E7: =INDEX(Scenario_Paths!E$10:E$12,MATCH($B$2,Scenario_Paths!$B$10:$B$12,0)) | F7: =INDEX(Scenario_Paths!F$10:F$12,MATCH($B$2,Scenario_Paths!$B$10:$B$12,0)) | G7: =INDEX(Scenario_Paths!G$10:G$12,MATCH($B$2,Scenario_Paths!$B$10:$B$12,0)) | H7: =INDEX(Scenario_Paths!H$10:H$12,MATCH($B$2,Scenario_Paths!$B$10:$B$12,0)) | I7: =INDEX(Scenario_Paths!I$10:I$12,MATCH($B$2,Scenario_Paths!$B$10:$B$12,0)) | J7: =INDEX(Scenario_Paths!J$10:J$12,MATCH($B$2,Scenario_Paths!$B$10:$B$12,0)) | ... L7: =INDEX(Scenario_Paths!L$10:L$12,MATCH($B$2,Scenario_Paths!$B$10:$B$12,0))
A8: Revenue | B8: =Case_Inputs!$C$16*(1-$B$3) | C8: =B8*(1+C6) | D8: =C8*(1+D6) | E8: =D8*(1+E6) | F8: =E8*(1+F6) | G8: =F8*(1+G6) | H8: =G8*(1+H6) | I8: =H8*(1+I6) | J8: =I8*(1+J6) | ... L8: =K8*(1+L6)
A9: Sticky cost of churned ARR (col B = churned ARR base) | B9: =Case_Inputs!$C$16*$B$3*(1+C6) | C9: =$B$9*Assumptions!$D$15 | D9: =$B$9*Assumptions!$D$15*0.5 | E9: 0 | F9: 0 | G9: 0 | H9: 0 | I9: 0 | J9: 0 | K9: 0 | L9: 0
A10: EBITDA | C10: =C8*C7-C9 | D10: =D8*D7-D9 | E10: =E8*E7-E9 | F10: =F8*F7-F9 | G10: =G8*G7-G9 | H10: =H8*H7-H9 | I10: =I8*I7-I9 | J10: =J8*J7-J9 | ... L10: =L8*L7-L9
A11: D&A | C11: =Assumptions!$D$12*C8 | D11: =Assumptions!$D$12*D8 | E11: =Assumptions!$D$12*E8 | F11: =Assumptions!$D$12*F8 | G11: =Assumptions!$D$12*G8 | H11: =Assumptions!$D$12*H8 | I11: =Assumptions!$D$12*I8 | J11: =Assumptions!$D$12*J8 | ... L11: =Assumptions!$D$12*L8
A12: EBIT | C12: =C10-C11 | D12: =D10-D11 | E12: =E10-E11 | F12: =F10-F11 | G12: =G10-G11 | H12: =H10-H11 | I12: =I10-I11 | J12: =J10-J11 | ... L12: =L10-L11
A13: Tax | C13: =MAX(C12,0)*Assumptions!$D$5 | D13: =MAX(D12,0)*Assumptions!$D$5 | E13: =MAX(E12,0)*Assumptions!$D$5 | F13: =MAX(F12,0)*Assumptions!$D$5 | G13: =MAX(G12,0)*Assumptions!$D$5 | H13: =MAX(H12,0)*Assumptions!$D$5 | I13: =MAX(I12,0)*Assumptions!$D$5 | J13: =MAX(J12,0)*Assumptions!$D$5 | ... L13: =MAX(L12,0)*Assumptions!$D$5
A14: PAT | C14: =C12-C13 | D14: =D12-D13 | E14: =E12-E13 | F14: =F12-F13 | G14: =G12-G13 | H14: =H12-H13 | I14: =I12-I13 | J14: =J12-J13 | ... L14: =L12-L13
A15: Capex | C15: =Assumptions!$D$13*C8 | D15: =Assumptions!$D$13*D8 | E15: =Assumptions!$D$13*E8 | F15: =Assumptions!$D$13*F8 | G15: =Assumptions!$D$13*G8 | H15: =Assumptions!$D$13*H8 | I15: =Assumptions!$D$13*I8 | J15: =Assumptions!$D$13*J8 | ... L15: =Assumptions!$D$13*L8
A16: Change in NWC | C16: =Assumptions!$D$14*(C8-B8) | D16: =Assumptions!$D$14*(D8-C8) | E16: =Assumptions!$D$14*(E8-D8) | F16: =Assumptions!$D$14*(F8-E8) | G16: =Assumptions!$D$14*(G8-F8) | H16: =Assumptions!$D$14*(H8-G8) | I16: =Assumptions!$D$14*(I8-H8) | J16: =Assumptions!$D$14*(J8-I8) | ... L16: =Assumptions!$D$14*(L8-K8)
A17: FCF | C17: =C10-C13-C15-C16 | D17: =D10-D13-D15-D16 | E17: =E10-E13-E15-E16 | F17: =F10-F13-F15-F16 | G17: =G10-G13-G15-G16 | H17: =H10-H13-H15-H16 | I17: =I10-I13-I15-I16 | J17: =J10-J13-J15-J16 | ... L17: =L10-L13-L15-L16
A18: Discount factor | C18: =1/(1+Assumptions!$D$10)^1 | D18: =1/(1+Assumptions!$D$10)^2 | E18: =1/(1+Assumptions!$D$10)^3 | F18: =1/(1+Assumptions!$D$10)^4 | G18: =1/(1+Assumptions!$D$10)^5 | H18: =1/(1+Assumptions!$D$10)^6 | I18: =1/(1+Assumptions!$D$10)^7 | J18: =1/(1+Assumptions!$D$10)^8 | K18: =1/(1+Assumptions!$D$10)^9 | L18: =1/(1+Assumptions!$D$10)^10
A19: PV of FCF | C19: =C17*C18 | D19: =D17*D18 | E19: =E17*E18 | F19: =F17*F18 | G19: =G17*G18 | H19: =H17*H18 | I19: =I17*I18 | J19: =J17*J18 | ... L19: =L17*L18
A20: Terminal value (PV) | B20: =L17*(1+Assumptions!$D$11)/(Assumptions!$D$10-Assumptions!$D$11)*L18
A21: Liminal enterprise value | B21: =SUM(C19:L19)+B20
A24: Scenario | B24: base
A25: Churn applied | B25: 0
A27: Liminal (standalone) | B27: FY26 | C27: FY27 | D27: FY28 | E27: FY29 | F27: FY30 | G27: FY31 | H27: FY32 | I27: FY33 | J27: FY34 | K27: FY35 | L27: FY36
A28: Growth | C28: =INDEX(Scenario_Paths!C$5:C$7,MATCH($B$24,Scenario_Paths!$B$5:$B$7,0)) | D28: =INDEX(Scenario_Paths!D$5:D$7,MATCH($B$24,Scenario_Paths!$B$5:$B$7,0)) | E28: =INDEX(Scenario_Paths!E$5:E$7,MATCH($B$24,Scenario_Paths!$B$5:$B$7,0)) | F28: =INDEX(Scenario_Paths!F$5:F$7,MATCH($B$24,Scenario_Paths!$B$5:$B$7,0)) | G28: =INDEX(Scenario_Paths!G$5:G$7,MATCH($B$24,Scenario_Paths!$B$5:$B$7,0)) | H28: =INDEX(Scenario_Paths!H$5:H$7,MATCH($B$24,Scenario_Paths!$B$5:$B$7,0)) | I28: =INDEX(Scenario_Paths!I$5:I$7,MATCH($B$24,Scenario_Paths!$B$5:$B$7,0)) | J28: =INDEX(Scenario_Paths!J$5:J$7,MATCH($B$24,Scenario_Paths!$B$5:$B$7,0)) | ... L28: =INDEX(Scenario_Paths!L$5:L$7,MATCH($B$24,Scenario_Paths!$B$5:$B$7,0))
A29: Margin | C29: =INDEX(Scenario_Paths!C$10:C$12,MATCH($B$24,Scenario_Paths!$B$10:$B$12,0)) | D29: =INDEX(Scenario_Paths!D$10:D$12,MATCH($B$24,Scenario_Paths!$B$10:$B$12,0)) | E29: =INDEX(Scenario_Paths!E$10:E$12,MATCH($B$24,Scenario_Paths!$B$10:$B$12,0)) | F29: =INDEX(Scenario_Paths!F$10:F$12,MATCH($B$24,Scenario_Paths!$B$10:$B$12,0)) | G29: =INDEX(Scenario_Paths!G$10:G$12,MATCH($B$24,Scenario_Paths!$B$10:$B$12,0)) | H29: =INDEX(Scenario_Paths!H$10:H$12,MATCH($B$24,Scenario_Paths!$B$10:$B$12,0)) | I29: =INDEX(Scenario_Paths!I$10:I$12,MATCH($B$24,Scenario_Paths!$B$10:$B$12,0)) | J29: =INDEX(Scenario_Paths!J$10:J$12,MATCH($B$24,Scenario_Paths!$B$10:$B$12,0)) | ... L29: =INDEX(Scenario_Paths!L$10:L$12,MATCH($B$24,Scenario_Paths!$B$10:$B$12,0))
A30: Revenue | B30: =Case_Inputs!$C$16*(1-$B$25) | C30: =B30*(1+C28) | D30: =C30*(1+D28) | E30: =D30*(1+E28) | F30: =E30*(1+F28) | G30: =F30*(1+G28) | H30: =G30*(1+H28) | I30: =H30*(1+I28) | J30: =I30*(1+J28) | ... L30: =K30*(1+L28)
A31: Sticky cost of churned ARR (col B = churned ARR base) | B31: =Case_Inputs!$C$16*$B$25*(1+C28) | C31: =$B$31*Assumptions!$D$15 | D31: =$B$31*Assumptions!$D$15*0.5 | E31: 0 | F31: 0 | G31: 0 | H31: 0 | I31: 0 | J31: 0 | K31: 0 | L31: 0
A32: EBITDA | C32: =C30*C29-C31 | D32: =D30*D29-D31 | E32: =E30*E29-E31 | F32: =F30*F29-F31 | G32: =G30*G29-G31 | H32: =H30*H29-H31 | I32: =I30*I29-I31 | J32: =J30*J29-J31 | ... L32: =L30*L29-L31
A33: D&A | C33: =Assumptions!$D$12*C30 | D33: =Assumptions!$D$12*D30 | E33: =Assumptions!$D$12*E30 | F33: =Assumptions!$D$12*F30 | G33: =Assumptions!$D$12*G30 | H33: =Assumptions!$D$12*H30 | I33: =Assumptions!$D$12*I30 | J33: =Assumptions!$D$12*J30 | ... L33: =Assumptions!$D$12*L30
A34: EBIT | C34: =C32-C33 | D34: =D32-D33 | E34: =E32-E33 | F34: =F32-F33 | G34: =G32-G33 | H34: =H32-H33 | I34: =I32-I33 | J34: =J32-J33 | ... L34: =L32-L33
A35: Tax | C35: =MAX(C34,0)*Assumptions!$D$5 | D35: =MAX(D34,0)*Assumptions!$D$5 | E35: =MAX(E34,0)*Assumptions!$D$5 | F35: =MAX(F34,0)*Assumptions!$D$5 | G35: =MAX(G34,0)*Assumptions!$D$5 | H35: =MAX(H34,0)*Assumptions!$D$5 | I35: =MAX(I34,0)*Assumptions!$D$5 | J35: =MAX(J34,0)*Assumptions!$D$5 | ... L35: =MAX(L34,0)*Assumptions!$D$5
A36: PAT | C36: =C34-C35 | D36: =D34-D35 | E36: =E34-E35 | F36: =F34-F35 | G36: =G34-G35 | H36: =H34-H35 | I36: =I34-I35 | J36: =J34-J35 | ... L36: =L34-L35
A37: Capex | C37: =Assumptions!$D$13*C30 | D37: =Assumptions!$D$13*D30 | E37: =Assumptions!$D$13*E30 | F37: =Assumptions!$D$13*F30 | G37: =Assumptions!$D$13*G30 | H37: =Assumptions!$D$13*H30 | I37: =Assumptions!$D$13*I30 | J37: =Assumptions!$D$13*J30 | ... L37: =Assumptions!$D$13*L30
A38: Change in NWC | C38: =Assumptions!$D$14*(C30-B30) | D38: =Assumptions!$D$14*(D30-C30) | E38: =Assumptions!$D$14*(E30-D30) | F38: =Assumptions!$D$14*(F30-E30) | G38: =Assumptions!$D$14*(G30-F30) | H38: =Assumptions!$D$14*(H30-G30) | I38: =Assumptions!$D$14*(I30-H30) | J38: =Assumptions!$D$14*(J30-I30) | ... L38: =Assumptions!$D$14*(L30-K30)
A39: FCF | C39: =C32-C35-C37-C38 | D39: =D32-D35-D37-D38 | E39: =E32-E35-E37-E38 | F39: =F32-F35-F37-F38 | G39: =G32-G35-G37-G38 | H39: =H32-H35-H37-H38 | I39: =I32-I35-I37-I38 | J39: =J32-J35-J37-J38 | ... L39: =L32-L35-L37-L38
A40: Discount factor | C40: =1/(1+Assumptions!$D$10)^1 | D40: =1/(1+Assumptions!$D$10)^2 | E40: =1/(1+Assumptions!$D$10)^3 | F40: =1/(1+Assumptions!$D$10)^4 | G40: =1/(1+Assumptions!$D$10)^5 | H40: =1/(1+Assumptions!$D$10)^6 | I40: =1/(1+Assumptions!$D$10)^7 | J40: =1/(1+Assumptions!$D$10)^8 | K40: =1/(1+Assumptions!$D$10)^9 | L40: =1/(1+Assumptions!$D$10)^10
A41: PV of FCF | C41: =C39*C40 | D41: =D39*D40 | E41: =E39*E40 | F41: =F39*F40 | G41: =G39*G40 | H41: =H39*H40 | I41: =I39*I40 | J41: =J39*J40 | ... L41: =L39*L40
A42: Terminal value (PV) | B42: =L39*(1+Assumptions!$D$11)/(Assumptions!$D$10-Assumptions!$D$11)*L40
A43: Liminal enterprise value | B43: =SUM(C41:L41)+B42
A46: Scenario | B46: bull
...

Sheet DCF_Sensitivity
A1: Liminal EV sensitivity, base, no churn (values from model run)
A2: Rows: discount rate. Columns: terminal growth.
A4: Discount rate | B4: g 5.0% | C4: g 5.5% | D4: g 6.0% | E4: g 6.5% | F4: g 7.0%
A5: 0.15 | B5: 1696 | C5: 1754 | D5: 1819 | E5: 1891 | F5: 1972
A6: 0.16 | B6: 1489 | C6: 1533 | D6: 1582 | E6: 1636 | F6: 1696
A7: 0.17 | B7: 1319 | C7: 1353 | D7: 1391 | E7: 1432 | F7: 1477
A8: 0.18 | B8: 1178 | C8: 1205 | D8: 1234 | E8: 1266 | F8: 1300
A9: 0.19 | B9: 1058 | C9: 1080 | D9: 1103 | E9: 1128 | F9: 1155
A11: Liminal EV by scenario and churn (values)
A12: Scenario | B12: churn 0.0% | C12: churn 5.0% | D12: churn 15.0% | E12: churn 30.0% | F12: churn 37.5% | G12: churn 45.0% | H12: churn 60.0%
A13: bear | B13: 428 | C13: 398 | D13: 337 | E13: 243 | F13: 196 | G13: 149 | H13: 55
A14: base | B14: 1391 | C14: 1313 | D14: 1154 | E14: 915 | F14: 795 | G14: 673 | H14: 430
A15: bull | B15: 2398 | C15: 2269 | D15: 2009 | E15: 1615 | F15: 1418 | G15: 1221 | H15: 822

Sheet Full_Acq
A1: Full acquisition at ₹4,000 Cr: accretion/dilution, cash and NPV
A2: Case funding by default: ₹2,100 Cr balance-sheet cash + ₹1,900 Cr new Paytm shares
A3: Scenario | B3: base
A4: Churn | B4: =Assumptions!$D$16
A5: Annual capital drag | B5: =Case_Inputs!$C$18
A6: Cash from balance sheet | B6: =Case_Inputs!$C$14
A7: New debt | B7: 0
A8: New Paytm equity | B8: =Case_Inputs!$C$15
A9: Price | B9: =Case_Inputs!$C$13
A12: Liminal (standalone) | B12: FY26 | C12: FY27 | D12: FY28 | E12: FY29 | F12: FY30 | G12: FY31 | H12: FY32 | I12: FY33 | J12: FY34 | K12: FY35 | L12: FY36
A13: Growth | C13: =INDEX(Scenario_Paths!C$5:C$7,MATCH($B$3,Scenario_Paths!$B$5:$B$7,0)) | D13: =INDEX(Scenario_Paths!D$5:D$7,MATCH($B$3,Scenario_Paths!$B$5:$B$7,0)) | E13: =INDEX(Scenario_Paths!E$5:E$7,MATCH($B$3,Scenario_Paths!$B$5:$B$7,0)) | F13: =INDEX(Scenario_Paths!F$5:F$7,MATCH($B$3,Scenario_Paths!$B$5:$B$7,0)) | G13: =INDEX(Scenario_Paths!G$5:G$7,MATCH($B$3,Scenario_Paths!$B$5:$B$7,0)) | H13: =INDEX(Scenario_Paths!H$5:H$7,MATCH($B$3,Scenario_Paths!$B$5:$B$7,0)) | I13: =INDEX(Scenario_Paths!I$5:I$7,MATCH($B$3,Scenario_Paths!$B$5:$B$7,0)) | J13: =INDEX(Scenario_Paths!J$5:J$7,MATCH($B$3,Scenario_Paths!$B$5:$B$7,0)) | ... L13: =INDEX(Scenario_Paths!L$5:L$7,MATCH($B$3,Scenario_Paths!$B$5:$B$7,0))
A14: Margin | C14: =INDEX(Scenario_Paths!C$10:C$12,MATCH($B$3,Scenario_Paths!$B$10:$B$12,0)) | D14: =INDEX(Scenario_Paths!D$10:D$12,MATCH($B$3,Scenario_Paths!$B$10:$B$12,0)) | E14: =INDEX(Scenario_Paths!E$10:E$12,MATCH($B$3,Scenario_Paths!$B$10:$B$12,0)) | F14: =INDEX(Scenario_Paths!F$10:F$12,MATCH($B$3,Scenario_Paths!$B$10:$B$12,0)) | G14: =INDEX(Scenario_Paths!G$10:G$12,MATCH($B$3,Scenario_Paths!$B$10:$B$12,0)) | H14: =INDEX(Scenario_Paths!H$10:H$12,MATCH($B$3,Scenario_Paths!$B$10:$B$12,0)) | I14: =INDEX(Scenario_Paths!I$10:I$12,MATCH($B$3,Scenario_Paths!$B$10:$B$12,0)) | J14: =INDEX(Scenario_Paths!J$10:J$12,MATCH($B$3,Scenario_Paths!$B$10:$B$12,0)) | ... L14: =INDEX(Scenario_Paths!L$10:L$12,MATCH($B$3,Scenario_Paths!$B$10:$B$12,0))
A15: Revenue | B15: =Case_Inputs!$C$16*(1-$B$4) | C15: =B15*(1+C13) | D15: =C15*(1+D13) | E15: =D15*(1+E13) | F15: =E15*(1+F13) | G15: =F15*(1+G13) | H15: =G15*(1+H13) | I15: =H15*(1+I13) | J15: =I15*(1+J13) | ... L15: =K15*(1+L13)
A16: Sticky cost of churned ARR (col B = churned ARR base) | B16: =Case_Inputs!$C$16*$B$4*(1+C13) | C16: =$B$16*Assumptions!$D$15 | D16: =$B$16*Assumptions!$D$15*0.5 | E16: 0 | F16: 0 | G16: 0 | H16: 0 | I16: 0 | J16: 0 | K16: 0 | L16: 0
A17: EBITDA | C17: =C15*C14-C16 | D17: =D15*D14-D16 | E17: =E15*E14-E16 | F17: =F15*F14-F16 | G17: =G15*G14-G16 | H17: =H15*H14-H16 | I17: =I15*I14-I16 | J17: =J15*J14-J16 | ... L17: =L15*L14-L16
A18: D&A | C18: =Assumptions!$D$12*C15 | D18: =Assumptions!$D$12*D15 | E18: =Assumptions!$D$12*E15 | F18: =Assumptions!$D$12*F15 | G18: =Assumptions!$D$12*G15 | H18: =Assumptions!$D$12*H15 | I18: =Assumptions!$D$12*I15 | J18: =Assumptions!$D$12*J15 | ... L18: =Assumptions!$D$12*L15
A19: EBIT | C19: =C17-C18 | D19: =D17-D18 | E19: =E17-E18 | F19: =F17-F18 | G19: =G17-G18 | H19: =H17-H18 | I19: =I17-I18 | J19: =J17-J18 | ... L19: =L17-L18
A20: Tax | C20: =MAX(C19,0)*Assumptions!$D$5 | D20: =MAX(D19,0)*Assumptions!$D$5 | E20: =MAX(E19,0)*Assumptions!$D$5 | F20: =MAX(F19,0)*Assumptions!$D$5 | G20: =MAX(G19,0)*Assumptions!$D$5 | H20: =MAX(H19,0)*Assumptions!$D$5 | I20: =MAX(I19,0)*Assumptions!$D$5 | J20: =MAX(J19,0)*Assumptions!$D$5 | ... L20: =MAX(L19,0)*Assumptions!$D$5
A21: PAT | C21: =C19-C20 | D21: =D19-D20 | E21: =E19-E20 | F21: =F19-F20 | G21: =G19-G20 | H21: =H19-H20 | I21: =I19-I20 | J21: =J19-J20 | ... L21: =L19-L20
A22: Capex | C22: =Assumptions!$D$13*C15 | D22: =Assumptions!$D$13*D15 | E22: =Assumptions!$D$13*E15 | F22: =Assumptions!$D$13*F15 | G22: =Assumptions!$D$13*G15 | H22: =Assumptions!$D$13*H15 | I22: =Assumptions!$D$13*I15 | J22: =Assumptions!$D$13*J15 | ... L22: =Assumptions!$D$13*L15
A23: Change in NWC | C23: =Assumptions!$D$14*(C15-B15) | D23: =Assumptions!$D$14*(D15-C15) | E23: =Assumptions!$D$14*(E15-D15) | F23: =Assumptions!$D$14*(F15-E15) | G23: =Assumptions!$D$14*(G15-F15) | H23: =Assumptions!$D$14*(H15-G15) | I23: =Assumptions!$D$14*(I15-H15) | J23: =Assumptions!$D$14*(J15-I15) | ... L23: =Assumptions!$D$14*(L15-K15)
A24: FCF | C24: =C17-C20-C22-C23 | D24: =D17-D20-D22-D23 | E24: =E17-E20-E22-E23 | F24: =F17-F20-F22-F23 | G24: =G17-G20-G22-G23 | H24: =H17-H20-H22-H23 | I24: =I17-I20-I22-I23 | J24: =J17-J20-J22-J23 | ... L24: =L17-L20-L22-L23
A25: Discount factor | C25: =1/(1+Assumptions!$D$10)^1 | D25: =1/(1+Assumptions!$D$10)^2 | E25: =1/(1+Assumptions!$D$10)^3 | F25: =1/(1+Assumptions!$D$10)^4 | G25: =1/(1+Assumptions!$D$10)^5 | H25: =1/(1+Assumptions!$D$10)^6 | I25: =1/(1+Assumptions!$D$10)^7 | J25: =1/(1+Assumptions!$D$10)^8 | K25: =1/(1+Assumptions!$D$10)^9 | L25: =1/(1+Assumptions!$D$10)^10
A26: PV of FCF | C26: =C24*C25 | D26: =D24*D25 | E26: =E24*E25 | F26: =F24*F25 | G26: =G24*G25 | H26: =H24*H25 | I26: =I24*I25 | J26: =J24*J25 | ... L26: =L24*L25
A27: Terminal value (PV) | B27: =L24*(1+Assumptions!$D$11)/(Assumptions!$D$10-Assumptions!$D$11)*L25
A28: Liminal enterprise value | B28: =SUM(C26:L26)+B27
A30: Revenue synergy | C30: =INDEX(Scenario_Paths!C$15:C$17,MATCH($B$3,Scenario_Paths!$B$15:$B$17,0)) | D30: =INDEX(Scenario_Paths!D$15:D$17,MATCH($B$3,Scenario_Paths!$B$15:$B$17,0)) | E30: =INDEX(Scenario_Paths!E$15:E$17,MATCH($B$3,Scenario_Paths!$B$15:$B$17,0)) | F30: =INDEX(Scenario_Paths!F$15:F$17,MATCH($B$3,Scenario_Paths!$B$15:$B$17,0)) | G30: =INDEX(Scenario_Paths!G$15:G$17,MATCH($B$3,Scenario_Paths!$B$15:$B$17,0)) | H30: =INDEX(Scenario_Paths!H$15:H$17,MATCH($B$3,Scenario_Paths!$B$15:$B$17,0)) | I30: =INDEX(Scenario_Paths!I$15:I$17,MATCH($B$3,Scenario_Paths!$B$15:$B$17,0)) | J30: =INDEX(Scenario_Paths!J$15:J$17,MATCH($B$3,Scenario_Paths!$B$15:$B$17,0)) | ... L30: =INDEX(Scenario_Paths!L$15:L$17,MATCH($B$3,Scenario_Paths!$B$15:$B$17,0))
A31: Synergy after tax | C31: =C30*Assumptions!$D$25*(1-Assumptions!$D$5)*1 | D31: =D30*Assumptions!$D$25*(1-Assumptions!$D$5)*1 | E31: =E30*Assumptions!$D$25*(1-Assumptions!$D$5)*1 | F31: =F30*Assumptions!$D$25*(1-Assumptions!$D$5)*1 | G31: =G30*Assumptions!$D$25*(1-Assumptions!$D$5)*1 | H31: =H30*Assumptions!$D$25*(1-Assumptions!$D$5)*1 | I31: =I30*Assumptions!$D$25*(1-Assumptions!$D$5)*1 | J31: =J30*Assumptions!$D$25*(1-Assumptions!$D$5)*1 | ... L31: =L30*Assumptions!$D$25*(1-Assumptions!$D$5)*1
A32: Paytm discount factor | C32: =1/(1+Assumptions!$D$9)^1 | D32: =1/(1+Assumptions!$D$9)^2 | E32: =1/(1+Assumptions!$D$9)^3 | F32: =1/(1+Assumptions!$D$9)^4 | G32: =1/(1+Assumptions!$D$9)^5 | H32: =1/(1+Assumptions!$D$9)^6 | I32: =1/(1+Assumptions!$D$9)^7 | J32: =1/(1+Assumptions!$D$9)^8 | K32: =1/(1+Assumptions!$D$9)^9 | L32: =1/(1+Assumptions!$D$9)^10
A33: Synergy PV (incl. terminal) | B33: =SUMPRODUCT(C31:L31,C32:L32)+L31*(1+Assumptions!$D$26)/(Assumptions!$D$9-Assumptions!$D$26)*L32
A35: Paytm deal build | C35: 2027 | D35: 2028 | E35: 2029 | F35: 2030 | G35: 2031 | H35: 2032 | I35: 2033 | J35: 2034 | K35: 2035 | L35: 2036
A36: Cumulative locked reserves | C36: =$B$5 | D36: =C36+$B$5 | E36: =D36+$B$5 | F36: =E36+$B$5 | G36: =F36+$B$5 | H36: =G36+$B$5 | I36: =H36+$B$5 | J36: =I36+$B$5 | K36: =J36+$B$5 | L36: =K36+$B$5
A37: Forgone interest on cash | C37: =$B$6*Assumptions!$D$6 | D37: =$B$6*Assumptions!$D$6 | E37: =$B$6*Assumptions!$D$6 | F37: =$B$6*Assumptions!$D$6 | G37: =$B$6*Assumptions!$D$6 | H37: =$B$6*Assumptions!$D$6 | I37: =$B$6*Assumptions!$D$6 | J37: =$B$6*Assumptions!$D$6 | ... L37: =$B$6*Assumptions!$D$6
A38: Interest on new debt | C38: =$B$7*Assumptions!$D$7 | D38: =$B$7*Assumptions!$D$7 | E38: =$B$7*Assumptions!$D$7 | F38: =$B$7*Assumptions!$D$7 | G38: =$B$7*Assumptions!$D$7 | H38: =$B$7*Assumptions!$D$7 | I38: =$B$7*Assumptions!$D$7 | J38: =$B$7*Assumptions!$D$7 | ... L38: =$B$7*Assumptions!$D$7
A39: Negative carry on reserves | C39: =C36*(Assumptions!$D$6-Assumptions!$D$8) | D39: =D36*(Assumptions!$D$6-Assumptions!$D$8) | E39: =E36*(Assumptions!$D$6-Assumptions!$D$8) | F39: =F36*(Assumptions!$D$6-Assumptions!$D$8) | G39: =G36*(Assumptions!$D$6-Assumptions!$D$8) | H39: =H36*(Assumptions!$D$6-Assumptions!$D$8) | I39: =I36*(Assumptions!$D$6-Assumptions!$D$8) | J39: =J36*(Assumptions!$D$6-Assumptions!$D$8) | ... L39: =L36*(Assumptions!$D$6-Assumptions!$D$8)
A40: Governance cost | C40: =Assumptions!$D$21 | D40: =Assumptions!$D$21 | E40: =Assumptions!$D$21 | F40: =Assumptions!$D$21 | G40: =Assumptions!$D$21 | H40: =Assumptions!$D$21 | I40: =Assumptions!$D$21 | J40: =Assumptions!$D$21 | ... L40: =Assumptions!$D$21
A41: PPA amortisation | C41: =Assumptions!$D$22 | D41: =Assumptions!$D$22 | E41: =Assumptions!$D$22 | F41: =Assumptions!$D$22 | G41: =Assumptions!$D$22 | H41: =Assumptions!$D$22 | I41: =Assumptions!$D$22 | J41: =Assumptions!$D$22 | ... L41: =Assumptions!$D$22
A42: Transaction costs | C42: =Assumptions!$D$23 | D42: 0 | E42: 0 | F42: 0 | G42: 0 | H42: 0 | I42: 0 | J42: 0 | K42: 0 | L42: 0
A43: Pre-tax deal costs | C43: =SUM(C37:C42) | D43: =SUM(D37:D42) | E43: =SUM(E37:E42) | F43: =SUM(F37:F42) | G43: =SUM(G37:G42) | H43: =SUM(H37:H42) | I43: =SUM(I37:I42) | J43: =SUM(J37:J42) | ... L43: =SUM(L37:L42)
A44: Deal ΔPAT | C44: =-C43*(1-Assumptions!$D$5)+C21+C31+Assumptions!$D$24*(1-Assumptions!$D$5) | D44: =-D43*(1-Assumptions!$D$5)+D21+D31+Assumptions!$D$24*(1-Assumptions!$D$5) | E44: =-E43*(1-Assumptions!$D$5)+E21+E31+Assumptions!$D$24*(1-Assumptions!$D$5) | F44: =-F43*(1-Assumptions!$D$5)+F21+F31+Assumptions!$D$24*(1-Assumptions!$D$5) | G44: =-G43*(1-Assumptions!$D$5)+G21+G31+Assumptions!$D$24*(1-Assumptions!$D$5) | H44: =-H43*(1-Assumptions!$D$5)+H21+H31+Assumptions!$D$24*(1-Assumptions!$D$5) | I44: =-I43*(1-Assumptions!$D$5)+I21+I31+Assumptions!$D$24*(1-Assumptions!$D$5) | J44: =-J43*(1-Assumptions!$D$5)+J21+J31+Assumptions!$D$24*(1-Assumptions!$D$5) | ... L44: =-L43*(1-Assumptions!$D$5)+L21+L31+Assumptions!$D$24*(1-Assumptions!$D$5)
...

Sheet Minority
A1: Recommended: 24.9% stake + licence + ROFR + call option
A2: ₹400 Cr upfront cash (₹250 Cr primary + ₹150 Cr secondary), Tranche 2 up to ₹600 Cr on FY29 ARR
A3: Scenario | B3: base
A4: Churn | B4: =Assumptions!$D$17
A5: Annual capital drag | B5: =Assumptions!$D$20
A6: Stake | B6: =Assumptions!$D$29
A7: Upfront cash | B7: =Assumptions!$D$30
A10: Liminal (standalone) | B10: FY26 | C10: FY27 | D10: FY28 | E10: FY29 | F10: FY30 | G10: FY31 | H10: FY32 | I10: FY33 | J10: FY34 | K10: FY35 | L10: FY36
A11: Growth | C11: =INDEX(Scenario_Paths!C$5:C$7,MATCH($B$3,Scenario_Paths!$B$5:$B$7,0)) | D11: =INDEX(Scenario_Paths!D$5:D$7,MATCH($B$3,Scenario_Paths!$B$5:$B$7,0)) | E11: =INDEX(Scenario_Paths!E$5:E$7,MATCH($B$3,Scenario_Paths!$B$5:$B$7,0)) | F11: =INDEX(Scenario_Paths!F$5:F$7,MATCH($B$3,Scenario_Paths!$B$5:$B$7,0)) | G11: =INDEX(Scenario_Paths!G$5:G$7,MATCH($B$3,Scenario_Paths!$B$5:$B$7,0)) | H11: =INDEX(Scenario_Paths!H$5:H$7,MATCH($B$3,Scenario_Paths!$B$5:$B$7,0)) | I11: =INDEX(Scenario_Paths!I$5:I$7,MATCH($B$3,Scenario_Paths!$B$5:$B$7,0)) | J11: =INDEX(Scenario_Paths!J$5:J$7,MATCH($B$3,Scenario_Paths!$B$5:$B$7,0)) | ... L11: =INDEX(Scenario_Paths!L$5:L$7,MATCH($B$3,Scenario_Paths!$B$5:$B$7,0))
A12: Margin | C12: =INDEX(Scenario_Paths!C$10:C$12,MATCH($B$3,Scenario_Paths!$B$10:$B$12,0)) | D12: =INDEX(Scenario_Paths!D$10:D$12,MATCH($B$3,Scenario_Paths!$B$10:$B$12,0)) | E12: =INDEX(Scenario_Paths!E$10:E$12,MATCH($B$3,Scenario_Paths!$B$10:$B$12,0)) | F12: =INDEX(Scenario_Paths!F$10:F$12,MATCH($B$3,Scenario_Paths!$B$10:$B$12,0)) | G12: =INDEX(Scenario_Paths!G$10:G$12,MATCH($B$3,Scenario_Paths!$B$10:$B$12,0)) | H12: =INDEX(Scenario_Paths!H$10:H$12,MATCH($B$3,Scenario_Paths!$B$10:$B$12,0)) | I12: =INDEX(Scenario_Paths!I$10:I$12,MATCH($B$3,Scenario_Paths!$B$10:$B$12,0)) | J12: =INDEX(Scenario_Paths!J$10:J$12,MATCH($B$3,Scenario_Paths!$B$10:$B$12,0)) | ... L12: =INDEX(Scenario_Paths!L$10:L$12,MATCH($B$3,Scenario_Paths!$B$10:$B$12,0))
A13: Revenue | B13: =Case_Inputs!$C$16*(1-$B$4) | C13: =B13*(1+C11) | D13: =C13*(1+D11) | E13: =D13*(1+E11) | F13: =E13*(1+F11) | G13: =F13*(1+G11) | H13: =G13*(1+H11) | I13: =H13*(1+I11) | J13: =I13*(1+J11) | ... L13: =K13*(1+L11)
A14: Sticky cost of churned ARR (col B = churned ARR base) | B14: =Case_Inputs!$C$16*$B$4*(1+C11) | C14: =$B$14*Assumptions!$D$15 | D14: =$B$14*Assumptions!$D$15*0.5 | E14: 0 | F14: 0 | G14: 0 | H14: 0 | I14: 0 | J14: 0 | K14: 0 | L14: 0
A15: EBITDA | C15: =C13*C12-C14 | D15: =D13*D12-D14 | E15: =E13*E12-E14 | F15: =F13*F12-F14 | G15: =G13*G12-G14 | H15: =H13*H12-H14 | I15: =I13*I12-I14 | J15: =J13*J12-J14 | ... L15: =L13*L12-L14
A16: D&A | C16: =Assumptions!$D$12*C13 | D16: =Assumptions!$D$12*D13 | E16: =Assumptions!$D$12*E13 | F16: =Assumptions!$D$12*F13 | G16: =Assumptions!$D$12*G13 | H16: =Assumptions!$D$12*H13 | I16: =Assumptions!$D$12*I13 | J16: =Assumptions!$D$12*J13 | ... L16: =Assumptions!$D$12*L13
A17: EBIT | C17: =C15-C16 | D17: =D15-D16 | E17: =E15-E16 | F17: =F15-F16 | G17: =G15-G16 | H17: =H15-H16 | I17: =I15-I16 | J17: =J15-J16 | ... L17: =L15-L16
A18: Tax | C18: =MAX(C17,0)*Assumptions!$D$5 | D18: =MAX(D17,0)*Assumptions!$D$5 | E18: =MAX(E17,0)*Assumptions!$D$5 | F18: =MAX(F17,0)*Assumptions!$D$5 | G18: =MAX(G17,0)*Assumptions!$D$5 | H18: =MAX(H17,0)*Assumptions!$D$5 | I18: =MAX(I17,0)*Assumptions!$D$5 | J18: =MAX(J17,0)*Assumptions!$D$5 | ... L18: =MAX(L17,0)*Assumptions!$D$5
A19: PAT | C19: =C17-C18 | D19: =D17-D18 | E19: =E17-E18 | F19: =F17-F18 | G19: =G17-G18 | H19: =H17-H18 | I19: =I17-I18 | J19: =J17-J18 | ... L19: =L17-L18
A20: Capex | C20: =Assumptions!$D$13*C13 | D20: =Assumptions!$D$13*D13 | E20: =Assumptions!$D$13*E13 | F20: =Assumptions!$D$13*F13 | G20: =Assumptions!$D$13*G13 | H20: =Assumptions!$D$13*H13 | I20: =Assumptions!$D$13*I13 | J20: =Assumptions!$D$13*J13 | ... L20: =Assumptions!$D$13*L13
A21: Change in NWC | C21: =Assumptions!$D$14*(C13-B13) | D21: =Assumptions!$D$14*(D13-C13) | E21: =Assumptions!$D$14*(E13-D13) | F21: =Assumptions!$D$14*(F13-E13) | G21: =Assumptions!$D$14*(G13-F13) | H21: =Assumptions!$D$14*(H13-G13) | I21: =Assumptions!$D$14*(I13-H13) | J21: =Assumptions!$D$14*(J13-I13) | ... L21: =Assumptions!$D$14*(L13-K13)
A22: FCF | C22: =C15-C18-C20-C21 | D22: =D15-D18-D20-D21 | E22: =E15-E18-E20-E21 | F22: =F15-F18-F20-F21 | G22: =G15-G18-G20-G21 | H22: =H15-H18-H20-H21 | I22: =I15-I18-I20-I21 | J22: =J15-J18-J20-J21 | ... L22: =L15-L18-L20-L21
A23: Discount factor | C23: =1/(1+Assumptions!$D$10)^1 | D23: =1/(1+Assumptions!$D$10)^2 | E23: =1/(1+Assumptions!$D$10)^3 | F23: =1/(1+Assumptions!$D$10)^4 | G23: =1/(1+Assumptions!$D$10)^5 | H23: =1/(1+Assumptions!$D$10)^6 | I23: =1/(1+Assumptions!$D$10)^7 | J23: =1/(1+Assumptions!$D$10)^8 | K23: =1/(1+Assumptions!$D$10)^9 | L23: =1/(1+Assumptions!$D$10)^10
A24: PV of FCF | C24: =C22*C23 | D24: =D22*D23 | E24: =E22*E23 | F24: =F22*F23 | G24: =G22*G23 | H24: =H22*H23 | I24: =I22*I23 | J24: =J22*J23 | ... L24: =L22*L23
A25: Terminal value (PV) | B25: =L22*(1+Assumptions!$D$11)/(Assumptions!$D$10-Assumptions!$D$11)*L23
A26: Liminal enterprise value | B26: =SUM(C24:L24)+B25
A28: Revenue synergy | C28: =INDEX(Scenario_Paths!C$15:C$17,MATCH($B$3,Scenario_Paths!$B$15:$B$17,0)) | D28: =INDEX(Scenario_Paths!D$15:D$17,MATCH($B$3,Scenario_Paths!$B$15:$B$17,0)) | E28: =INDEX(Scenario_Paths!E$15:E$17,MATCH($B$3,Scenario_Paths!$B$15:$B$17,0)) | F28: =INDEX(Scenario_Paths!F$15:F$17,MATCH($B$3,Scenario_Paths!$B$15:$B$17,0)) | G28: =INDEX(Scenario_Paths!G$15:G$17,MATCH($B$3,Scenario_Paths!$B$15:$B$17,0)) | H28: =INDEX(Scenario_Paths!H$15:H$17,MATCH($B$3,Scenario_Paths!$B$15:$B$17,0)) | I28: =INDEX(Scenario_Paths!I$15:I$17,MATCH($B$3,Scenario_Paths!$B$15:$B$17,0)) | J28: =INDEX(Scenario_Paths!J$15:J$17,MATCH($B$3,Scenario_Paths!$B$15:$B$17,0)) | ... L28: =INDEX(Scenario_Paths!L$15:L$17,MATCH($B$3,Scenario_Paths!$B$15:$B$17,0))
A29: Synergy after tax | C29: =C28*Assumptions!$D$25*(1-Assumptions!$D$5)*Assumptions!$D$27 | D29: =D28*Assumptions!$D$25*(1-Assumptions!$D$5)*Assumptions!$D$27 | E29: =E28*Assumptions!$D$25*(1-Assumptions!$D$5)*Assumptions!$D$27 | F29: =F28*Assumptions!$D$25*(1-Assumptions!$D$5)*Assumptions!$D$27 | G29: =G28*Assumptions!$D$25*(1-Assumptions!$D$5)*Assumptions!$D$27 | H29: =H28*Assumptions!$D$25*(1-Assumptions!$D$5)*Assumptions!$D$27 | I29: =I28*Assumptions!$D$25*(1-Assumptions!$D$5)*Assumptions!$D$27 | J29: =J28*Assumptions!$D$25*(1-Assumptions!$D$5)*Assumptions!$D$27 | ... L29: =L28*Assumptions!$D$25*(1-Assumptions!$D$5)*Assumptions!$D$27
A30: Paytm discount factor | C30: =1/(1+Assumptions!$D$9)^1 | D30: =1/(1+Assumptions!$D$9)^2 | E30: =1/(1+Assumptions!$D$9)^3 | F30: =1/(1+Assumptions!$D$9)^4 | G30: =1/(1+Assumptions!$D$9)^5 | H30: =1/(1+Assumptions!$D$9)^6 | I30: =1/(1+Assumptions!$D$9)^7 | J30: =1/(1+Assumptions!$D$9)^8 | K30: =1/(1+Assumptions!$D$9)^9 | L30: =1/(1+Assumptions!$D$9)^10
A31: Synergy PV (incl. terminal) | B31: =SUMPRODUCT(C29:L29,C30:L30)+L29*(1+Assumptions!$D$26)/(Assumptions!$D$9-Assumptions!$D$26)*L30
A33: Tranche 2 payable (FY30) | B33: =Assumptions!$D$32*MIN(MAX((E13-Assumptions!$D$33)/(Assumptions!$D$34-Assumptions!$D$33),0),1)
A35: Paytm deal build | C35: 2027 | D35: 2028 | E35: 2029 | F35: 2030 | G35: 2031 | H35: 2032 | I35: 2033 | J35: 2034 | K35: 2035 | L35: 2036
A36: Cumulative cash paid | C36: =$B$7+IF(0>=3,$B$33,0) | D36: =$B$7+IF(1>=3,$B$33,0) | E36: =$B$7+IF(2>=3,$B$33,0) | F36: =$B$7+IF(3>=3,$B$33,0) | G36: =$B$7+IF(4>=3,$B$33,0) | H36: =$B$7+IF(5>=3,$B$33,0) | I36: =$B$7+IF(6>=3,$B$33,0) | J36: =$B$7+IF(7>=3,$B$33,0) | K36: =$B$7+IF(8>=3,$B$33,0) | L36: =$B$7+IF(9>=3,$B$33,0)
A37: Forgone interest | C37: =-C36*Assumptions!$D$6*(1-Assumptions!$D$5) | D37: =-D36*Assumptions!$D$6*(1-Assumptions!$D$5) | E37: =-E36*Assumptions!$D$6*(1-Assumptions!$D$5) | F37: =-F36*Assumptions!$D$6*(1-Assumptions!$D$5) | G37: =-G36*Assumptions!$D$6*(1-Assumptions!$D$5) | H37: =-H36*Assumptions!$D$6*(1-Assumptions!$D$5) | I37: =-I36*Assumptions!$D$6*(1-Assumptions!$D$5) | J37: =-J36*Assumptions!$D$6*(1-Assumptions!$D$5) | ... L37: =-L36*Assumptions!$D$6*(1-Assumptions!$D$5)
A38: Licence fee | C38: =-Assumptions!$D$28*(1-Assumptions!$D$5) | D38: =-Assumptions!$D$28*(1-Assumptions!$D$5) | E38: =-Assumptions!$D$28*(1-Assumptions!$D$5) | F38: =-Assumptions!$D$28*(1-Assumptions!$D$5) | G38: =-Assumptions!$D$28*(1-Assumptions!$D$5) | H38: =-Assumptions!$D$28*(1-Assumptions!$D$5) | I38: =-Assumptions!$D$28*(1-Assumptions!$D$5) | J38: =-Assumptions!$D$28*(1-Assumptions!$D$5) | ... L38: =-Assumptions!$D$28*(1-Assumptions!$D$5)
A39: Avoided build | C39: =Assumptions!$D$24*(1-Assumptions!$D$5) | D39: =Assumptions!$D$24*(1-Assumptions!$D$5) | E39: =Assumptions!$D$24*(1-Assumptions!$D$5) | F39: =Assumptions!$D$24*(1-Assumptions!$D$5) | G39: =Assumptions!$D$24*(1-Assumptions!$D$5) | H39: =Assumptions!$D$24*(1-Assumptions!$D$5) | I39: =Assumptions!$D$24*(1-Assumptions!$D$5) | J39: =Assumptions!$D$24*(1-Assumptions!$D$5) | ... L39: =Assumptions!$D$24*(1-Assumptions!$D$5)
A40: Synergy retained (after tax) | C40: =C29 | D40: =D29 | E40: =E29 | F40: =F29 | G40: =G29 | H40: =H29 | I40: =I29 | J40: =J29 | ... L40: =L29
A41: Equity-method income | C41: =$B$6*(C19+Assumptions!$D$31*Assumptions!$D$6*(1-Assumptions!$D$5)) | D41: =$B$6*(D19+Assumptions!$D$31*Assumptions!$D$6*(1-Assumptions!$D$5)) | E41: =$B$6*(E19+Assumptions!$D$31*Assumptions!$D$6*(1-Assumptions!$D$5)) | F41: =$B$6*(F19+Assumptions!$D$31*Assumptions!$D$6*(1-Assumptions!$D$5)) | G41: =$B$6*(G19+Assumptions!$D$31*Assumptions!$D$6*(1-Assumptions!$D$5)) | H41: =$B$6*(H19+Assumptions!$D$31*Assumptions!$D$6*(1-Assumptions!$D$5)) | I41: =$B$6*(I19+Assumptions!$D$31*Assumptions!$D$6*(1-Assumptions!$D$5)) | J41: =$B$6*(J19+Assumptions!$D$31*Assumptions!$D$6*(1-Assumptions!$D$5)) | ... L41: =$B$6*(L19+Assumptions!$D$31*Assumptions!$D$6*(1-Assumptions!$D$5))
A42: Deal ΔPAT | C42: =SUM(C37:C41) | D42: =SUM(D37:D41) | E42: =SUM(E37:E41) | F42: =SUM(F37:F41) | G42: =SUM(G37:G41) | H42: =SUM(H37:H41) | I42: =SUM(I37:I41) | J42: =SUM(J37:J41) | ... L42: =SUM(L37:L41)
A43: Pro-forma EPS (₹) | C43: =(Case_Inputs!$C$11+Case_Inputs!$C$19*(1-Assumptions!$D$5)+C42)/Case_Inputs!$C$6 | D43: =(Case_Inputs!$C$11+Case_Inputs!$C$19*(1-Assumptions!$D$5)+D42)/Case_Inputs!$C$6 | E43: =(Case_Inputs!$C$11+Case_Inputs!$C$19*(1-Assumptions!$D$5)+E42)/Case_Inputs!$C$6 | F43: =(Case_Inputs!$C$11+Case_Inputs!$C$19*(1-Assumptions!$D$5)+F42)/Case_Inputs!$C$6 | G43: =(Case_Inputs!$C$11+Case_Inputs!$C$19*(1-Assumptions!$D$5)+G42)/Case_Inputs!$C$6 | H43: =(Case_Inputs!$C$11+Case_Inputs!$C$19*(1-Assumptions!$D$5)+H42)/Case_Inputs!$C$6 | I43: =(Case_Inputs!$C$11+Case_Inputs!$C$19*(1-Assumptions!$D$5)+I42)/Case_Inputs!$C$6 | J43: =(Case_Inputs!$C$11+Case_Inputs!$C$19*(1-Assumptions!$D$5)+J42)/Case_Inputs!$C$6 | ... L43: =(Case_Inputs!$C$11+Case_Inputs!$C$19*(1-Assumptions!$D$5)+L42)/Case_Inputs!$C$6
A44: EPS vs ₹7.50 | C44: =C43/Case_Inputs!$C$12-1 | D44: =D43/Case_Inputs!$C$12-1 | E44: =E43/Case_Inputs!$C$12-1 | F44: =F43/Case_Inputs!$C$12-1 | G44: =G43/Case_Inputs!$C$12-1 | H44: =H43/Case_Inputs!$C$12-1 | I44: =I43/Case_Inputs!$C$12-1 | J44: =J43/Case_Inputs!$C$12-1 | ... L44: =L43/Case_Inputs!$C$12-1
A45: PAT breakeven flag | C45: =IF(C42>=0,1,0) | D45: =IF(D42>=0,1,0) | E45: =IF(E42>=0,1,0) | F45: =IF(F42>=0,1,0) | G45: =IF(G42>=0,1,0) | H45: =IF(H42>=0,1,0) | I45: =IF(I42>=0,1,0) | J45: =IF(J42>=0,1,0) | ... L45: =IF(L42>=0,1,0)
...

Sheet JV
A1: 50:50 JV 'SettleCo' for tokenized settlement
A2: Paytm contributes ₹400 Cr cash; joint control attracts half the capital drag
A3: Scenario | B3: base
A4: Annual capital drag | B4: =Assumptions!$D$19
A6: JV build | C6: 2027 | D6: 2028 | E6: 2029 | F6: 2030 | G6: 2031 | H6: 2032 | I6: 2033 | J6: 2034 | K6: 2035 | L6: 2036
A7: Revenue synergy | C7: =INDEX(Scenario_Paths!C$15:C$17,MATCH($B$3,Scenario_Paths!$B$15:$B$17,0)) | D7: =INDEX(Scenario_Paths!D$15:D$17,MATCH($B$3,Scenario_Paths!$B$15:$B$17,0)) | E7: =INDEX(Scenario_Paths!E$15:E$17,MATCH($B$3,Scenario_Paths!$B$15:$B$17,0)) | F7: =INDEX(Scenario_Paths!F$15:F$17,MATCH($B$3,Scenario_Paths!$B$15:$B$17,0)) | G7: =INDEX(Scenario_Paths!G$15:G$17,MATCH($B$3,Scenario_Paths!$B$15:$B$17,0)) | H7: =INDEX(Scenario_Paths!H$15:H$17,MATCH($B$3,Scenario_Paths!$B$15:$B$17,0)) | I7: =INDEX(Scenario_Paths!I$15:I$17,MATCH($B$3,Scenario_Paths!$B$15:$B$17,0)) | J7: =INDEX(Scenario_Paths!J$15:J$17,MATCH($B$3,Scenario_Paths!$B$15:$B$17,0)) | ... L7: =INDEX(Scenario_Paths!L$15:L$17,MATCH($B$3,Scenario_Paths!$B$15:$B$17,0))
A8: JV PAT | C8: =(C7*Assumptions!$D$25-IF(0<2,Assumptions!$D$36,0))*(1-Assumptions!$D$5) | D8: =(D7*Assumptions!$D$25-IF(1<2,Assumptions!$D$36,0))*(1-Assumptions!$D$5) | E8: =(E7*Assumptions!$D$25-IF(2<2,Assumptions!$D$36,0))*(1-Assumptions!$D$5) | F8: =(F7*Assumptions!$D$25-IF(3<2,Assumptions!$D$36,0))*(1-Assumptions!$D$5) | G8: =(G7*Assumptions!$D$25-IF(4<2,Assumptions!$D$36,0))*(1-Assumptions!$D$5) | H8: =(H7*Assumptions!$D$25-IF(5<2,Assumptions!$D$36,0))*(1-Assumptions!$D$5) | I8: =(I7*Assumptions!$D$25-IF(6<2,Assumptions!$D$36,0))*(1-Assumptions!$D$5) | J8: =(J7*Assumptions!$D$25-IF(7<2,Assumptions!$D$36,0))*(1-Assumptions!$D$5) | K8: =(K7*Assumptions!$D$25-IF(8<2,Assumptions!$D$36,0))*(1-Assumptions!$D$5) | L8: =(L7*Assumptions!$D$25-IF(9<2,Assumptions!$D$36,0))*(1-Assumptions!$D$5)
A9: Paytm 50% share | C9: =0.5*C8 | D9: =0.5*D8 | E9: =0.5*E8 | F9: =0.5*F8 | G9: =0.5*G8 | H9: =0.5*H8 | I9: =0.5*I8 | J9: =0.5*J8 | ... L9: =0.5*L8
A10: Paytm discount factor | C10: =1/(1+Assumptions!$D$9)^1 | D10: =1/(1+Assumptions!$D$9)^2 | E10: =1/(1+Assumptions!$D$9)^3 | F10: =1/(1+Assumptions!$D$9)^4 | G10: =1/(1+Assumptions!$D$9)^5 | H10: =1/(1+Assumptions!$D$9)^6 | I10: =1/(1+Assumptions!$D$9)^7 | J10: =1/(1+Assumptions!$D$9)^8 | K10: =1/(1+Assumptions!$D$9)^9 | L10: =1/(1+Assumptions!$D$9)^10
A11: Pro-forma EPS (₹) | C11: =(Case_Inputs!$C$11+Case_Inputs!$C$19*(1-Assumptions!$D$5)-Assumptions!$D$35*Assumptions!$D$6*(1-Assumptions!$D$5)+C9+Assumptions!$D$24*(1-Assumptions!$D$5))/Case_Inputs!$C$6 | D11: =(Case_Inputs!$C$11+Case_Inputs!$C$19*(1-Assumptions!$D$5)-Assumptions!$D$35*Assumptions!$D$6*(1-Assumptions!$D$5)+D9+Assumptions!$D$24*(1-Assumptions!$D$5))/Case_Inputs!$C$6 | E11: =(Case_Inputs!$C$11+Case_Inputs!$C$19*(1-Assumptions!$D$5)-Assumptions!$D$35*Assumptions!$D$6*(1-Assumptions!$D$5)+E9+Assumptions!$D$24*(1-Assumptions!$D$5))/Case_Inputs!$C$6 | F11: =(Case_Inputs!$C$11+Case_Inputs!$C$19*(1-Assumptions!$D$5)-Assumptions!$D$35*Assumptions!$D$6*(1-Assumptions!$D$5)+F9+Assumptions!$D$24*(1-Assumptions!$D$5))/Case_Inputs!$C$6 | G11: =(Case_Inputs!$C$11+Case_Inputs!$C$19*(1-Assumptions!$D$5)-Assumptions!$D$35*Assumptions!$D$6*(1-Assumptions!$D$5)+G9+Assumptions!$D$24*(1-Assumptions!$D$5))/Case_Inputs!$C$6 | H11: =(Case_Inputs!$C$11+Case_Inputs!$C$19*(1-Assumptions!$D$5)-Assumptions!$D$35*Assumptions!$D$6*(1-Assumptions!$D$5)+H9+Assumptions!$D$24*(1-Assumptions!$D$5))/Case_Inputs!$C$6 | I11: =(Case_Inputs!$C$11+Case_Inputs!$C$19*(1-Assumptions!$D$5)-Assumptions!$D$35*Assumptions!$D$6*(1-Assumptions!$D$5)+I9+Assumptions!$D$24*(1-Assumptions!$D$5))/Case_Inputs!$C$6 | J11: =(Case_Inputs!$C$11+Case_Inputs!$C$19*(1-Assumptions!$D$5)-Assumptions!$D$35*Assumptions!$D$6*(1-Assumptions!$D$5)+J9+Assumptions!$D$24*(1-Assumptions!$D$5))/Case_Inputs!$C$6 | ... L11: =(Case_Inputs!$C$11+Case_Inputs!$C$19*(1-Assumptions!$D$5)-Assumptions!$D$35*Assumptions!$D$6*(1-Assumptions!$D$5)+L9+Assumptions!$D$24*(1-Assumptions!$D$5))/Case_Inputs!$C$6
A12: PAT breakeven flag | C12: =IF(C11>=Assumptions!$D$42,1,0) | D12: =IF(D11>=Assumptions!$D$42,1,0) | E12: =IF(E11>=Assumptions!$D$42,1,0) | F12: =IF(F11>=Assumptions!$D$42,1,0) | G12: =IF(G11>=Assumptions!$D$42,1,0) | H12: =IF(H11>=Assumptions!$D$42,1,0) | I12: =IF(I11>=Assumptions!$D$42,1,0) | J12: =IF(J11>=Assumptions!$D$42,1,0) | ... L12: =IF(L11>=Assumptions!$D$42,1,0)
A15: PV of Paytm JV share (incl. terminal) | B15: =SUMPRODUCT(C9:L9,C10:L10)+L9*(1+Assumptions!$D$26)/(Assumptions!$D$9-Assumptions!$D$26)*L10
A16: Avoided build PV | B16: =Assumptions!$D$43
A17: Cash contributed | B17: =Assumptions!$D$35
A18: PV of capital drag | B18: =$B$4/Assumptions!$D$9
A19: NPV to Paytm shareholders | B19: =B15+B16-B17-B18
A20: PAT breakeven year | B20: =IFERROR(INDEX(C6:L6,MATCH(1,C12:L12,0)),"Never (10 yrs)")

Sheet Walk_Away
A1: Walk away
A2: EPS benefits from the MDR regardless; strategic cost is the forgone synergy and the consortium owning Liminal
A4: EPS with MDR (₹) | B4: =Assumptions!$D$42
A5: NPV | B5: 0
A6: Forgone synergy PV, base (values from model run) | B6: 406
A7: Block on consortium | B7: None: licence can be terminated on change of control

Sheet Paths_Summary
A1: Four paths compared
A2: Live rows follow each sheet's selectors; scenario table and matrix below
A4: Live (per sheet selectors) | B4: Full acquisition | C4: 24.9% minority | D4: JV | E4: Walk away
A5: NPV | B5: =Full_Acq!$B$60 | C5: =Minority!$B$56 | D5: =JV!$B$19 | E5: =0
A6: FY27 EPS (₹) | B6: =Full_Acq!$C$47 | C6: =Minority!$C$43 | D6: =JV!$C$11 | E6: =Assumptions!$D$42
A7: PAT breakeven | B7: =Full_Acq!$B$62 | C7: =Minority!$B$57 | D7: =JV!$B$20 | E7: ="n/a"
A8: FCF breakeven | B8: =Full_Acq!$B$63 | C8: =Minority!$B$58 | D8: ="n/a" | E8: ="n/a"
A10: NPV by scenario (values from model run)
A11: Scenario | B11: Full acquisition | C11: 24.9% minority | D11: JV | E11: Walk away
A12: bear | B12: -8374 | C12: -113 | D12: -2613 | E12: 0
A13: base | B13: -7638 | C13: 211 | D13: -2544 | E13: 0
A14: bull | B14: -6892 | C14: 204 | D14: -2483 | E14: 0
A15: Probability-weighted (live) | B15: =B12*Assumptions!$D$37+B13*Assumptions!$D$38+B14*Assumptions!$D$39 | C15: =C12*Assumptions!$D$37+C13*Assumptions!$D$38+C14*Assumptions!$D$39 | D15: =D12*Assumptions!$D$37+D13*Assumptions!$D$38+D14*Assumptions!$D$39 | E15: =E12*Assumptions!$D$37+E13*Assumptions!$D$38+E14*Assumptions!$D$39
A17: Decision matrix (A28 weights, scores 1 to 5)
A18: Criterion | B18: Weight | C18: Full | D18: Minority | E18: JV | F18: Walk
A19: Shareholder value (NPV) | B19: 0.25 | C19: 1 | D19: 4 | E19: 2 | F19: 4
A20: EPS and FCF impact | B20: 0.15 | C20: 1 | D20: 4 | E20: 3 | F20: 5
A21: Balance sheet and rating | B21: 0.1 | C21: 2 | D21: 5 | E21: 4 | F21: 5
A22: Client churn risk | B22: 0.15 | C22: 1 | D22: 4 | E22: 4 | F22: 5
A23: Regulatory and capital drag exposure | B23: 0.1 | C23: 1 | D23: 4 | E23: 2 | F23: 5
A24: Strategic access to custody and tokenization | B24: 0.15 | C24: 5 | D24: 4 | E24: 3 | F24: 1
A25: Block on the consortium | B25: 0.1 | C25: 5 | D25: 4 | E25: 1 | F25: 1
A26: Weighted score | C26: =SUMPRODUCT($B$19:$B$25,C19:C25) | D26: =SUMPRODUCT($B$19:$B$25,D19:D25) | E26: =SUMPRODUCT($B$19:$B$25,E19:E25) | F26: =SUMPRODUCT($B$19:$B$25,F19:F25)

Sheet Churn_Drag_Grid
A1: Full acquisition stress tests (values from model run)
A2: NPV by churn and annual drag; maximum justified price; breakeven churn
A4: NPV grid, base
A5: Annual drag \ churn | B5: 0.0% | C5: 15.0% | D5: 30.0% | E5: 37.5% | F5: 45.0% | G5: 60.0%
A6: 0 | B6: -2203 | C6: -2440 | D6: -2679 | E6: -2799 | F6: -2921 | G6: -3164
A7: 250 | B7: -3816 | C7: -4053 | D7: -4292 | E7: -4412 | F7: -4534 | G7: -4777
A8: 500 | B8: -5429 | C8: -5666 | D8: -5905 | E8: -6025 | F8: -6147 | G8: -6390
A9: 750 | B9: -7042 | C9: -7279 | D9: -7518 | E9: -7638 | F9: -7760 | G9: -8002
A12: NPV grid, bull
A13: Annual drag \ churn | B13: 0.0% | C13: 15.0% | D13: 30.0% | E13: 37.5% | F13: 45.0% | G13: 60.0%
A14: 0 | B14: -1073 | C14: -1463 | D14: -1857 | E14: -2054 | F14: -2251 | G14: -2650
A15: 250 | B15: -2686 | C15: -3076 | D15: -3469 | E15: -3666 | F15: -3864 | G15: -4263
A16: 500 | B16: -4299 | C16: -4688 | D16: -5082 | E16: -5279 | F16: -5477 | G16: -5875
A17: 750 | B17: -5912 | C17: -6301 | D17: -6695 | E17: -6892 | F17: -7090 | G17: -7488
A20: NPV grid, bear
A21: Annual drag \ churn | B21: 0.0% | C21: 15.0% | D21: 30.0% | E21: 37.5% | F21: 45.0% | G21: 60.0%
A22: 0 | B22: -3303 | C22: -3395 | D22: -3488 | E22: -3535 | F22: -3583 | G22: -3677
A23: 250 | B23: -4916 | C23: -5007 | D23: -5101 | E23: -5148 | F23: -5195 | G23: -5290
A24: 500 | B24: -6529 | C24: -6620 | D24: -6714 | E24: -6761 | F24: -6808 | G24: -6902
A25: 750 | B25: -8142 | C25: -8233 | D25: -8327 | E25: -8374 | F25: -8421 | G25: -8515
A28: Maximum justified control price (churn | annual drag)
A29: Scenario | B29: 0|0 | C29: 0|750 | D29: 0.3|0 | E29: 0.3|750 | F29: 0.375|0 | G29: 0.375|750 | H29: 0.45|0 | I29: 0.45|750
A30: bear | B30: 697 | C30: -4142 | D30: 512 | E30: -4327 | F30: 465 | G30: -4374 | H30: 417 | I30: -4421
A31: base | B31: 1797 | C31: -3042 | D31: 1321 | E31: -3518 | F31: 1201 | G31: -3638 | H31: 1079 | I31: -3760
A32: bull | B32: 2927 | C32: -1912 | D32: 2143 | E32: -2695 | F32: 1946 | G32: -2892 | H32: 1749 | I32: -3090
A35: Breakeven churn (NPV = 0), zero drag
A36: Scenario | price | B36: Breakeven churn
A37: base|4000 | B37: No positive NPV at any churn
A38: base|3000 | B38: No positive NPV at any churn
A39: base|2000 | B39: No positive NPV at any churn
A40: base|1500 | B40: 0.1874
A41: bull|4000 | B41: No positive NPV at any churn
A42: bull|3000 | B42: No positive NPV at any churn
A43: bull|2000 | B43: 0.3544
A44: bull|1500 | B44: 0.5435
A45: minority bear | B45: No positive NPV at any churn
A46: minority base | B46: 0.5758
A47: minority bull | B47: 0.8623

Sheet Funding_Credit
A1: Funding mixes for the ₹4,000 Cr full acquisition vs the recommended structure
A2: Credit metrics live; EPS values from model run (base, 37.5% churn, ₹750 Cr drag)
A4: Mix | B4: Cash (₹ Cr) | C4: New debt | D4: New equity | E4: New shares (Cr) | F4: Dilution | G4: Gross debt/EBITDA | H4: Interest cover | I4: Cash after close | J4: FY27 EPS | K4: FY29 EPS | L4: FY27 EPS vs ₹7.50 | M4: NPV
A5: M1 cash 2100 + equity 1900 (case) | B5: 2100 | C5: 0 | D5: 1900 | E5: =D5/Assumptions!$D$41 | F5: =E5/Case_Inputs!$C$6 | G5: =(Case_Inputs!$C$8+C5)/Case_Inputs!$C$10 | H5: =Case_Inputs!$C$10/((Case_Inputs!$C$8+C5)*Assumptions!$D$7) | I5: =Case_Inputs!$C$7-B5 | J5: 4.702 | K5: 6.957 | L5: =J5/Case_Inputs!$C$12-1 | M5: -7638
A6: M2 debt 2100 + equity 1900 | B6: 0 | C6: 2100 | D6: 1900 | E6: =D6/Assumptions!$D$41 | F6: =E6/Case_Inputs!$C$6 | G6: =(Case_Inputs!$C$8+C6)/Case_Inputs!$C$10 | H6: =Case_Inputs!$C$10/((Case_Inputs!$C$8+C6)*Assumptions!$D$7) | I6: =Case_Inputs!$C$7-B6 | J6: 4.037 | K6: 6.293 | L6: =J6/Case_Inputs!$C$12-1 | M6: -7638
A7: M3 cash 1050 + debt 1050 + equity 1900 | B7: 1050 | C7: 1050 | D7: 1900 | E7: =D7/Assumptions!$D$41 | F7: =E7/Case_Inputs!$C$6 | G7: =(Case_Inputs!$C$8+C7)/Case_Inputs!$C$10 | H7: =Case_Inputs!$C$10/((Case_Inputs!$C$8+C7)*Assumptions!$D$7) | I7: =Case_Inputs!$C$7-B7 | J7: 4.37 | K7: 6.625 | L7: =J7/Case_Inputs!$C$12-1 | M7: -7638
A8: M4 all equity 4000 | B8: 0 | C8: 0 | D8: 4000 | E8: =D8/Assumptions!$D$41 | F8: =E8/Case_Inputs!$C$6 | G8: =(Case_Inputs!$C$8+C8)/Case_Inputs!$C$10 | H8: =Case_Inputs!$C$10/((Case_Inputs!$C$8+C8)*Assumptions!$D$7) | I8: =Case_Inputs!$C$7-B8 | J8: 6.047 | K8: 8.263 | L8: =J8/Case_Inputs!$C$12-1 | M8: -7638
A9: M5 all cash 4000 | B9: 4000 | C9: 0 | D9: 0 | E9: =D9/Assumptions!$D$41 | F9: =E9/Case_Inputs!$C$6 | G9: =(Case_Inputs!$C$8+C9)/Case_Inputs!$C$10 | H9: =Case_Inputs!$C$10/((Case_Inputs!$C$8+C9)*Assumptions!$D$7) | I9: =Case_Inputs!$C$7-B9 | J9: 3.444 | K9: 5.736 | L9: =J9/Case_Inputs!$C$12-1 | M9: -7638
A10: Recommended: 24.9% stake, all cash | B10: =Assumptions!$D$30 | C10: 0 | D10: 0 | E10: 0 | F10: 0 | G10: =Case_Inputs!$C$8/Case_Inputs!$C$10 | H10: =Case_Inputs!$C$10/(Case_Inputs!$C$8*Assumptions!$D$7) | I10: =Case_Inputs!$C$7-B10 | J10: =Minority!$C$43 | K10: =Minority!$E$43 | L10: =J10/Case_Inputs!$C$12-1 | M10: =Minority!$B$56

Sheet Football_Field
A1: Liminal valuation football field (100% equity) and the stake price rule
A2: DCF range from DCF_Sensitivity (g 6%, discount 19% to 15%)
A4: Method | B4: Low multiple (x ARR) | C4: High multiple (x ARR) | D4: Low ₹ Cr | E4: High ₹ Cr | F4: Midpoint | G4: Weight | H4: Note
A5: DCF (base, no churn) | D5: =DCF_Sensitivity!D9 | E5: =DCF_Sensitivity!D5 | F5: =(D5+E5)/2 | G5: 0.5
A6: Trading comps (EV/LTM revenue) | B6: 5.96 | C6: 8.35 | D6: =B6*Case_Inputs!$C$16 | E6: =C6*Case_Inputs!$C$16 | F6: =(D6+E6)/2 | G6: 0.3 | H6: 25th to 75th pct EV/LTM revenue, custody and high-growth fintech subset (Pine Labs, BitGo on gross profit, Adyen, Coinbase, PB Fintech), 23 Sep 2026
A7: Precedent transactions (EV/revenue) | B7: 7.8 | C7: 12.8 | D7: =B7*Case_Inputs!$C$16 | E7: =C7*Case_Inputs!$C$16 | F7: =(D7+E7)/2 | G7: 0.2 | H7: IQR of precedent EV/revenue with revenue basis (Bitstamp 2.1x, Deribit 9.7x, Hidden Road 12.5x, BVNK 12.5 to 15x)
A9: Weighted fair value (100%) | B9: =SUMPRODUCT(F5:F7,G5:G7)
A10: Weighted fair value / ARR (x) | B10: =B9/Case_Inputs!$C$16
A11: Stake price rule: 24.9% x fair value, rounded down to ₹50 Cr | B11: =FLOOR(Assumptions!$D$29*B9,50)
A12: Upfront price used (A24b) | B12: =Assumptions!$D$30
A13: Implied post-money | B13: =Assumptions!$D$30/Assumptions!$D$29
A14: Headline if Tranche 2 paid in full | B14: =(Assumptions!$D$30+Assumptions!$D$32)/Assumptions!$D$29
A15: Proposed deal price (case) | B15: =Case_Inputs!$C$13
A16: Proposed price / weighted fair value | B16: =B15/B9

Sheet Checks
A1: Model integrity checks (all must be TRUE with selectors at default)
A2: Python reference values from model_outputs.json
A4: Check | B4: Result
A5: Baseline EPS = PAT / shares = 7.50 | B5: =ABS(Case_Inputs!$C$11/Case_Inputs!$C$6-7.5)<0.001
A6: MDR-adjusted EPS = 8.845 | B6: =ABS(Assumptions!$D$42-8.845)<0.001
A7: Deal cash + equity = deal value | B7: =Case_Inputs!$C$14+Case_Inputs!$C$15=Case_Inputs!$C$13
A8: Liminal EV base, no churn ties to Python | B8: =ABS(Liminal_DCF!$B$43-1391)<=1
A9: Liminal EV bull, no churn ties to Python | B9: =ABS(Liminal_DCF!$B$65-2398)<=1
A10: Liminal EV bear, no churn ties to Python | B10: =ABS(Liminal_DCF!$B$21-428)<=1
A11: Full acquisition NPV (base) ties | B11: =ABS(Full_Acq!$B$60-(-7638))<=1
A12: Full acquisition FY27 EPS ties | B12: =ABS(Full_Acq!$C$47-4.702)<=0.005
A13: Minority NPV (base) ties | B13: =ABS(Minority!$B$56-(211))<=1
A14: Minority FY27 EPS ties | B14: =ABS(Minority!$C$43-8.79)<=0.005
A15: Minority Tranche 2 (base) ties | B15: =ABS(Minority!$B$33-0)<=1
A16: JV NPV (base) ties | B16: =ABS(JV!$B$19-(-2544))<=1
A17: JV FY27 EPS ties | B17: =ABS(JV!$C$11-8.798)<=0.005
A18: Decision matrix: minority ranks first | B18: =Paths_Summary!D26=MAX(Paths_Summary!C26:F26)
A19: Stake price rule equals upfront price used | B19: =Football_Field!B11=Football_Field!B12
A20: Probability weights sum to 1 | B20: =ABS(Assumptions!$D$37+Assumptions!$D$38+Assumptions!$D$39-1)<0.0001
A22: All checks pass | B22: =AND(B5:B20)
