Workbook

Sheet README
A1: Dream11 PIVOT '26 model, Team IdeaForge
A2: Values are pasted from model_outputs.json (the Python model is the source of truth).
A3: Yellow = inputs (case facts, researched facts, assumptions). Green = outputs. Checks sheet must show TRUE everywhere.
A4: Model run: 2026-09-29T19:17:39 hash: 9861e27587

Sheet Inputs
A1: Group | B1: Key | C1: Value
A2: F | B2: rev | C2: {"FY23": 6384, "FY24": 7934, "FY25": 6759}
A3: F | B3: pat | C3: {"FY23": 188, "FY24": 1295, "FY25": -479}
A4: F | B4: paid_share | C4: 0.95
A5: F | B5: dau_sep25_m | C5: 10
A6: F | B6: age_18_35 | C6: 0.7
A7: F | B7: watchalong_fans_m | C7: 30
A8: F | B8: users_feb26_m | C8: 250
A9: F | B9: users_aug26_m | C9: 300
A10: F | B10: bcci_deal_usd_m | C10: 44
A11: F | B11: staff | C11: 700
A12: F | B12: staff_left | C12: 0.15
A13: F | B13: gst_case | C13: 0.28
A14: R | B14: gst_statute | C14: 0.4
A15: R | B15: gst_pre2023_on_fee | C15: 0.18
... A21: A | B21: A01_preban_season_active_m | C21: 100
A22: A | B22: A02_seg_share | C22: {"S1": 0.35, "S2": 0.05, "S3": 0.2, "S4": 0.15, "S5": 0.25}
A23: A | B23: A03_seg_stay | C23: {"S1": 0.1, "S2": 0.05, "S3": 0.4, "S4": 0.35, "S5": 0.5}
A24: A | B24: A04_prize_removal_drop | C24: 0.3
A25: A | B25: A05_wtb0_m | C25: {"bear": 3.5, "base": 5.0, "bull": 6.5}
A26: A | B26: A06_nsm_curve | C26: [1.0, 1.05, 1.2, 1.35, 1.5, 2.3, 2.8, 2.4, 1.6, 1.7, 1.85, 2.0]
A27: A | B27: A07_curve_k | C27: {"bear": 0.5, "base": 1.0, "bull": 1.6}
A28: A | B28: A08_mau_elasticity | C28: 0.35
A29: A | B29: A09_core_sessions_wk | C29: 3
A30: A | B30: A10_imps_per_core_session | C30: 9
A31: A | B31: A11_casual_sessions_mo | C31: 3
A32: A | B32: A12_imps_per_casual_session | C32: 5
A33: A | B33: A13_fill | C33: 0.75
A34: A | B34: A14_ecpm | C34: {"regular": 110, "ipl": 180}
A35: A | B35: A15_ecpm_k | C35: {"bear": 0.75, "base": 1.0, "bull": 1.25}
A36: A | B36: A16_sponsor | C36: {"title_rating_season": {"bear": 15, "base": 30, "bull": 45}, "ipl_partners_n": {"bear": 3, "base": 5, "bull": 8}, "ipl_partner_cr": 5.0, "series_partners_n": {"bear": 2, "base": 4, "bull": 6}, "series_partner_cr": 2.5, "wpl_partner_cr": {"bear": 1.5, "base": 3.0, "bull": 4.5}}
A37: A | B37: A17_pro_price_mo | C37: 49
A38: A | B38: A18_pro_arppu_mo | C38: 33
A39: A | B39: A19_pro_conv_start | C39: {"bear": 0.005, "base": 0.01, "bull": 0.015}
A40: A | B40: A20_pro_conv_end | C40: {"bear": 0.01, "base": 0.02, "bull": 0.03}
A41: A | B41: A21_gift_payer_share | C41: 0.005
A42: A | B42: A22_gift_spend_mo | C42: 60
A43: A | B43: A23_gift_take | C43: 0.3
A44: A | B44: A24_fancode_ref_share | C44: 0.003
A45: A | B45: A25_fancode_pass_rs | C45: 99
...

Sheet Base_Segments
A1: ID | B1: Segment | C1: Pre-ban (M) | D1: Stay % | E1: Left (M) | F1: Now (M) | G1: Share %
A2: S1 | B2: Jackpot Hunters | C2: 35 | D2: 10 | E2: 31.5 | F2: 3.5 | G2: 7
A3: S2 | B3: Grinders | C3: 5 | D3: 5 | E3: 4.8 | F3: 0.2 | G3: 0.5
A4: S3 | B4: Cricket Brains | C4: 20 | D4: 40 | E4: 12 | F4: 8 | G4: 16
A5: S4 | B5: League Captains | C5: 15 | D5: 35 | E5: 9.8 | F5: 5.2 | G5: 10.5
A6: S5 | B6: Match-day Loungers | C6: 25 | D6: 50 | E6: 12.5 | F6: 33 | G6: 66

Sheet Options
A1: Option | B1: Fan pull without prizes | C1: Differentiation vs apps fans already open | D1: Fit with Dream11 assets | E1: Legal safety | F1: Revenue within 12 months | G1: Executable by the post-split team | H1: Weighted
A2: A. As declared: AI-first, global, multi-sport platform | B2: 2 | C2: 2 | D2: 3 | E2: 5 | F2: 2 | G2: 2 | H2: 2.6
A3: B. Fold Dream11 into FanCode | B3: 2 | C3: 3 | D3: 2 | E3: 5 | F3: 3 | G3: 3 | H3: 2.9
A4: C. Creator media network (watch-alongs first) | B4: 3 | C4: 1 | D4: 2 | E4: 5 | F4: 3 | G4: 3 | H4: 2.75
A5: D. Sharpen: India's free cricket skill league | B5: 4 | C5: 5 | D5: 5 | E5: 5 | F5: 3 | G5: 4 | H5: 4.35
A6: E. Wait for the court, return to paid fantasy | B6: 5 | C6: 4 | D6: 5 | E6: 1 | F6: 2 | G6: 2 | H6: 3.45

Sheet RICE
A1: Feature | B1: Reach | C1: Impact | D1: Confidence | E1: Effort | F1: RICE | G1: Cut
A2: Lineup-lock nudges | B2: 9 | C2: 1 | D2: 0.9 | E2: 3 | F2: 27 | G2: FALSE
A3: Dream Rating v1 | B3: 8 | C3: 3 | D3: 0.8 | E3: 10 | F3: 19.2 | G3: FALSE
A4: Leagues v2 | B4: 6 | C4: 3 | D4: 0.8 | E4: 8 | F4: 18 | G4: FALSE
A5: Shareable rating cards | B5: 6 | C5: 1 | D5: 0.8 | E5: 3 | F5: 16 | G5: FALSE
A6: Match-day digest | B6: 7 | C6: 1 | D6: 0.7 | E6: 5 | F6: 9.8 | G6: FALSE
A7: AI Scout at lineup lock | B7: 6 | C7: 2 | D7: 0.6 | E7: 9 | F7: 8 | G7: FALSE
A8: Creator-hosted leagues | B8: 4 | C8: 2 | D8: 0.6 | E8: 6 | F8: 8 | G8: FALSE
A9: Live Calls | B9: 5 | C9: 2 | D9: 0.6 | E9: 12 | F9: 5 | G9: FALSE
A10: AI Coach review | B10: 4 | C10: 2 | D10: 0.5 | E10: 8 | F10: 5 | G10: FALSE
A11: Session XI for Tests | B11: 2.5 | C11: 2 | D11: 0.6 | E11: 6 | F11: 5 | G11: FALSE
A12: FanCode play-along overlay | B12: 2 | C12: 2 | D12: 0.5 | E12: 10 | F12: 2 | G12: FALSE
A13: Dream11 Pro | B13: 1.5 | C13: 1 | D13: 0.6 | E13: 6 | F13: 1.5 | G13: FALSE
... A17: Global launch | B17: 1 | C17: 1 | D17: 0.2 | E17: 36 | F17: 0.1 | G17: TRUE

Sheet Revenue_bear
A1: Month | B1: NSM (M) | C1: MAU (M) | D1: Ads | E1: Sponsorship | F1: Pro | G1: Gifting | H1: FanCode | I1: Total | J1: Total (formula)
A2: Oct'26 | B2: 3.5 | C2: 35 | D2: 5.46 | E2: 1.25 | F2: 0 | G2: 0.03 | H2: 0.02 | I2: 6.75 | J2: =SUM(D2:H2)
A3: Nov'26 | B3: 3.59 | C3: 35.3 | D3: 5.54 | E3: 0 | F3: 0 | G3: 0.03 | H3: 0.02 | I3: 5.59 | J3: =SUM(D3:H3)
A4: Dec'26 | B4: 3.85 | C4: 36.2 | D4: 5.79 | E4: 1.25 | F4: 0 | G4: 0.03 | H4: 0.02 | I4: 7.09 | J4: =SUM(D4:H4)
A5: Jan'27 | B5: 4.11 | C5: 37.1 | D5: 6.04 | E5: 3.67 | F5: 0 | G5: 0.04 | H5: 0.02 | I5: 9.76 | J5: =SUM(D5:H5)
A6: Feb'27 | B6: 4.38 | C6: 38.1 | D6: 6.29 | E6: 3.67 | F6: 0 | G6: 0.04 | H6: 0.02 | I6: 10.02 | J6: =SUM(D6:H6)
A7: Mar'27 | B7: 5.77 | C7: 43 | D7: 11.03 | E7: 6.44 | F7: 0.1 | G7: 0.05 | H7: 0.03 | I7: 17.64 | J7: =SUM(D7:H7)
A8: Apr'27 | B8: 6.65 | C8: 46 | D8: 13.85 | E8: 8.48 | F8: 0.13 | G8: 0.06 | H8: 0.03 | I8: 22.55 | J8: =SUM(D8:H8)
A9: May'27 | B9: 5.95 | C9: 43.6 | D9: 10.28 | E9: 5.08 | F9: 0.13 | G9: 0.05 | H9: 0.03 | I9: 15.56 | J9: =SUM(D9:H9)
A10: Jun'27 | B10: 4.55 | C10: 38.7 | D10: 6.46 | E10: 1.67 | F10: 0.11 | G10: 0.04 | H10: 0.02 | I10: 8.3 | J10: =SUM(D10:H10)
A11: Jul'27 | B11: 4.73 | C11: 39.3 | D11: 6.63 | E11: 1.67 | F11: 0.13 | G11: 0.04 | H11: 0.02 | I11: 8.49 | J11: =SUM(D11:H11)
A12: Aug'27 | B12: 4.99 | C12: 40.2 | D12: 6.88 | E12: 1.67 | F12: 0.15 | G12: 0.04 | H12: 0.02 | I12: 8.76 | J12: =SUM(D12:H12)
A13: Sep'27 | B13: 5.25 | C13: 41.1 | D13: 7.13 | E13: 1.67 | F13: 0.17 | G13: 0.05 | H13: 0.02 | I13: 9.04 | J13: =SUM(D13:H13)
A15: 12 months | D15: =SUM(D2:D13) | E15: =SUM(E2:E13) | F15: =SUM(F2:F13) | G15: =SUM(G2:G13) | H15: =SUM(H2:H13) | I15: =SUM(I2:I13)

Sheet Revenue_base
A1: Month | B1: NSM (M) | C1: MAU (M) | D1: Ads | E1: Sponsorship | F1: Pro | G1: Gifting | H1: FanCode | I1: Total | J1: Total (formula)
A2: Oct'26 | B2: 5 | C2: 35 | D2: 8.54 | E2: 2.5 | F2: 0 | G2: 0.04 | H2: 0.02 | I2: 11.1 | J2: =SUM(D2:H2)
A3: Nov'26 | B3: 5.25 | C3: 35.6 | D3: 8.82 | E3: 0 | F3: 0 | G3: 0.05 | H3: 0.02 | I3: 8.89 | J3: =SUM(D3:H3)
A4: Dec'26 | B4: 6 | C4: 37.5 | D4: 9.68 | E4: 2.5 | F4: 0 | G4: 0.05 | H4: 0.03 | I4: 12.26 | J4: =SUM(D4:H4)
A5: Jan'27 | B5: 6.75 | C5: 39.3 | D5: 10.54 | E5: 7.33 | F5: 0 | G5: 0.06 | H5: 0.03 | I5: 17.96 | J5: =SUM(D5:H5)
A6: Feb'27 | B6: 7.5 | C6: 41.1 | D6: 11.39 | E6: 7.33 | F6: 0 | G6: 0.07 | H6: 0.03 | I6: 18.83 | J6: =SUM(D6:H6)
A7: Mar'27 | B7: 11.5 | C7: 50.9 | D7: 23.08 | E7: 11.29 | F7: 0.38 | G7: 0.1 | H7: 0.05 | I7: 34.91 | J7: =SUM(D7:H7)
A8: Apr'27 | B8: 14 | C8: 57 | D8: 30.81 | E8: 14.7 | F8: 0.54 | G8: 0.13 | H8: 0.06 | I8: 46.24 | J8: =SUM(D8:H8)
A9: May'27 | B9: 12 | C9: 52.1 | D9: 21.81 | E9: 9.02 | F9: 0.53 | G9: 0.11 | H9: 0.05 | I9: 31.51 | J9: =SUM(D9:H9)
A10: Jun'27 | B10: 8 | C10: 42.4 | D10: 11.97 | E10: 3.33 | F10: 0.4 | G10: 0.07 | H10: 0.04 | I10: 15.8 | J10: =SUM(D10:H10)
A11: Jul'27 | B11: 8.5 | C11: 43.6 | D11: 12.54 | E11: 3.33 | F11: 0.47 | G11: 0.08 | H11: 0.04 | I11: 16.45 | J11: =SUM(D11:H11)
A12: Aug'27 | B12: 9.25 | C12: 45.4 | D12: 13.4 | E12: 3.33 | F12: 0.56 | G12: 0.08 | H12: 0.04 | I12: 17.41 | J12: =SUM(D12:H12)
A13: Sep'27 | B13: 10 | C13: 47.2 | D13: 14.25 | E13: 3.33 | F13: 0.66 | G13: 0.09 | H13: 0.04 | I13: 18.38 | J13: =SUM(D13:H13)
A15: 12 months | D15: =SUM(D2:D13) | E15: =SUM(E2:E13) | F15: =SUM(F2:F13) | G15: =SUM(G2:G13) | H15: =SUM(H2:H13) | I15: =SUM(I2:I13)

Sheet Revenue_bull
A1: Month | B1: NSM (M) | C1: MAU (M) | D1: Ads | E1: Sponsorship | F1: Pro | G1: Gifting | H1: FanCode | I1: Total | J1: Total (formula)
A2: Oct'26 | B2: 6.5 | C2: 35 | D2: 12.25 | E2: 3.75 | F2: 0 | G2: 0.06 | H2: 0.03 | I2: 16.08 | J2: =SUM(D2:H2)
A3: Nov'26 | B3: 7.02 | C3: 36 | D3: 12.94 | E3: 0 | F3: 0 | G3: 0.06 | H3: 0.03 | I3: 13.04 | J3: =SUM(D3:H3)
A4: Dec'26 | B4: 8.58 | C4: 38.9 | D4: 15.04 | E4: 3.75 | F4: 0 | G4: 0.08 | H4: 0.04 | I4: 18.9 | J4: =SUM(D4:H4)
A5: Jan'27 | B5: 10.14 | C5: 41.9 | D5: 17.13 | E5: 11 | F5: 0 | G5: 0.09 | H5: 0.05 | I5: 28.27 | J5: =SUM(D5:H5)
A6: Feb'27 | B6: 11.7 | C6: 44.8 | D6: 19.23 | E6: 11 | F6: 0 | G6: 0.11 | H6: 0.05 | I6: 30.38 | J6: =SUM(D6:H6)
A7: Mar'27 | B7: 20.02 | C7: 60.5 | D7: 43.94 | E7: 17.73 | F7: 0.99 | G7: 0.18 | H7: 0.09 | I7: 62.92 | J7: =SUM(D7:H7)
A8: Apr'27 | B8: 25.22 | C8: 70.3 | D8: 61.16 | E8: 23.18 | F8: 1.46 | G8: 0.23 | H8: 0.11 | I8: 86.14 | J8: =SUM(D8:H8)
A9: May'27 | B9: 21.06 | C9: 62.4 | D9: 41.91 | E9: 14.09 | F9: 1.39 | G9: 0.19 | H9: 0.09 | I9: 57.67 | J9: =SUM(D9:H9)
A10: Jun'27 | B10: 12.74 | C10: 46.8 | D10: 20.62 | E10: 5 | F10: 0.95 | G10: 0.11 | H10: 0.06 | I10: 26.74 | J10: =SUM(D10:H10)
A11: Jul'27 | B11: 13.78 | C11: 48.7 | D11: 22.02 | E11: 5 | F11: 1.14 | G11: 0.12 | H11: 0.06 | I11: 28.34 | J11: =SUM(D11:H11)
A12: Aug'27 | B12: 15.34 | C12: 51.7 | D12: 24.11 | E12: 5 | F12: 1.39 | G12: 0.14 | H12: 0.07 | I12: 30.71 | J12: =SUM(D12:H12)
A13: Sep'27 | B13: 16.9 | C13: 54.6 | D13: 26.21 | E13: 5 | F13: 1.67 | G13: 0.15 | H13: 0.08 | I13: 33.11 | J13: =SUM(D13:H13)
A15: 12 months | D15: =SUM(D2:D13) | E15: =SUM(E2:E13) | F15: =SUM(F2:F13) | G15: =SUM(G2:G13) | H15: =SUM(H2:H13) | I15: =SUM(I2:I13)

Sheet Stress
A1: Deposit case | B1: Deposit ratio | C1: Net pre-2023 | D1: GST 28% | E1: Net 28% | F1: GST 40% | G1: Net 40% | H1: Drop 28 % | I1: Drop 40 % | J1: Prize pool 28 %
A2: bear | B2: 0.7 | C2: 12.71 | D2: 19.6 | E2: -4.6 | F2: 28 | G2: -13 | H2: 136.2 | I2: 202.3 | J2: 67.7
A3: base | B3: 0.5 | C3: 12.71 | D3: 14 | E3: 1 | F3: 20 | G3: -5 | H3: 92.1 | I3: 139.3 | J3: 73.3
A4: bull | B4: 0.35 | C4: 12.71 | D4: 9.8 | E4: 5.2 | F4: 14 | G4: 1 | H4: 59.1 | I4: 92.1 | J4: 77.5

Sheet Sensitivity
A1: NSM baseline (M) | B1: eCPM 82 | C1: eCPM 96 | D1: eCPM 110 | E1: eCPM 124 | F1: eCPM 138
A2: 3 | B2: 172.9 | C2: 189.9 | D2: 206.9 | E2: 223.9 | F2: 240.9
A3: 4 | B3: 189.2 | C3: 208.8 | D3: 228.3 | E3: 247.9 | F3: 267.4
A4: 5 | B4: 205.6 | C4: 227.7 | D4: 249.7 | E4: 271.9 | F4: 294
A5: 6 | B5: 221.9 | C5: 246.5 | D5: 271.2 | E5: 295.9 | F5: 320.5
A6: 7 | B6: 238.2 | C6: 265.4 | D6: 292.6 | E6: 319.8 | F6: 347

Sheet Checks
A1: Check | B1: Result
A2: Base 12-month total ties to JSON | B2: =ABS(Revenue_base!I15-249.7)<=0.5
A3: Bear 12-month total ties | B3: =ABS(Revenue_bear!I15-129.6)<=0.5
A4: Bull 12-month total ties | B4: =ABS(Revenue_bull!I15-432.3)<=0.5
A5: Monthly totals equal stream sums (base) | B5: =SUMPRODUCT(ABS(Revenue_base!I2:I13-Revenue_base!J2:J13))<=0.2
A6: Option D ranks first | B6: =Options!H5=MAX(Options!H2:H6)
A7: Stress mid net at 28% below pre-2023 | B7: =Stress!E3<Stress!C3
A8: Segments now sum to mid-2026 MAU | B8: =ABS(SUM(Base_Segments!F2:F6)-50.0)<=0.3
A9: All checks pass | B9: =AND(B2:B8)
